Workbook

Sheet Dashboard
A1: GASTOS PESSOAIS — RENATO BREIA
A3: ▼ SAÍDAS POR CATEGORIA
A4: Categoria | B4: 2025-07 | C4: 2025-08 | D4: 2025-09 | E4: 2025-10 | F4: 2025-11 | G4: 2025-12 | H4: 2026-01 | I4: 2026-02 | J4: 2026-03 | K4: Total
A5: Alimentação | B5: =IFERROR(-(SUMIFS('Itaú CC'!$C:$C,'Itaú CC'!$E:$E,$A5,'Itaú CC'!$F:$F,B$4,'Itaú CC'!$D:$D,"saída")+SUMIFS('Itaú Cartão'!$C:$C,'Itaú Cartão'!$E:$E,$A5,'Itaú Cartão'!$F:$F,B$4,'Itaú Cartão'!$D:$D,"saída")+SUMIFS('BTG Cartão'!$C:$C,'BTG Cartão'!$E:$E,$A5,'BTG Cartão'!$F:$F,B$4,'BTG Cartão'!$D:$D,"saída")),0) | C5: =IFERROR(-(SUMIFS('Itaú CC'!$C:$C,'Itaú CC'!$E:$E,$A5,'Itaú CC'!$F:$F,C$4,'Itaú CC'!$D:$D,"saída")+SUMIFS('Itaú Cartão'!$C:$C,'Itaú Cartão'!$E:$E,$A5,'Itaú Cartão'!$F:$F,C$4,'Itaú Cartão'!$D:$D,"saída")+SUMIFS('BTG Cartão'!$C:$C,'BTG Cartão'!$E:$E,$A5,'BTG Cartão'!$F:$F,C$4,'BTG Cartão'!$D:$D,"saída")),0) | D5: =IFERROR(-(SUMIFS('Itaú CC'!$C:$C,'Itaú CC'!$E:$E,$A5,'Itaú CC'!$F:$F,D$4,'Itaú CC'!$D:$D,"saída")+SUMIFS('Itaú Cartão'!$C:$C,'Itaú Cartão'!$E:$E,$A5,'Itaú Cartão'!$F:$F,D$4,'Itaú Cartão'!$D:$D,"saída")+SUMIFS('BTG Cartão'!$C:$C,'BTG Cartão'!$E:$E,$A5,'BTG Cartão'!$F:$F,D$4,'BTG Cartão'!$D:$D,"saída")),0) | E5: =IFERROR(-(SUMIFS('Itaú CC'!$C:$C,'Itaú CC'!$E:$E,$A5,'Itaú CC'!$F:$F,E$4,'Itaú CC'!$D:$D,"saída")+SUMIFS('Itaú Cartão'!$C:$C,'Itaú Cartão'!$E:$E,$A5,'Itaú Cartão'!$F:$F,E$4,'Itaú Cartão'!$D:$D,"saída")+SUMIFS('BTG Cartão'!$C:$C,'BTG Cartão'!$E:$E,$A5,'BTG Cartão'!$F:$F,E$4,'BTG Cartão'!$D:$D,"saída")),0) | F5: =IFERROR(-(SUMIFS('Itaú CC'!$C:$C,'Itaú CC'!$E:$E,$A5,'Itaú CC'!$F:$F,F$4,'Itaú CC'!$D:$D,"saída")+SUMIFS('Itaú Cartão'!$C:$C,'Itaú Cartão'!$E:$E,$A5,'Itaú Cartão'!$F:$F,F$4,'Itaú Cartão'!$D:$D,"saída")+SUMIFS('BTG Cartão'!$C:$C,'BTG Cartão'!$E:$E,$A5,'BTG Cartão'!$F:$F,F$4,'BTG Cartão'!$D:$D,"saída")),0) | G5: =IFERROR(-(SUMIFS('Itaú CC'!$C:$C,'Itaú CC'!$E:$E,$A5,'Itaú CC'!$F:$F,G$4,'Itaú CC'!$D:$D,"saída")+SUMIFS('Itaú Cartão'!$C:$C,'Itaú Cartão'!$E:$E,$A5,'Itaú Cartão'!$F:$F,G$4,'Itaú Cartão'!$D:$D,"saída")+SUMIFS('BTG Cartão'!$C:$C,'BTG Cartão'!$E:$E,$A5,'BTG Cartão'!$F:$F,G$4,'BTG Cartão'!$D:$D,"saída")),0) | H5: =IFERROR(-(SUMIFS('Itaú CC'!$C:$C,'Itaú CC'!$E:$E,$A5,'Itaú CC'!$F:$F,H$4,'Itaú CC'!$D:$D,"saída")+SUMIFS('Itaú Cartão'!$C:$C,'Itaú Cartão'!$E:$E,$A5,'Itaú Cartão'!$F:$F,H$4,'Itaú Cartão'!$D:$D,"saída")+SUMIFS('BTG Cartão'!$C:$C,'BTG Cartão'!$E:$E,$A5,'BTG Cartão'!$F:$F,H$4,'BTG Cartão'!$D:$D,"saída")),0) | I5: =IFERROR(-(SUMIFS('Itaú CC'!$C:$C,'Itaú CC'!$E:$E,$A5,'Itaú CC'!$F:$F,I$4,'Itaú CC'!$D:$D,"saída")+SUMIFS('Itaú Cartão'!$C:$C,'Itaú Cartão'!$E:$E,$A5,'Itaú Cartão'!$F:$F,I$4,'Itaú Cartão'!$D:$D,"saída")+SUMIFS('BTG Cartão'!$C:$C,'BTG Cartão'!$E:$E,$A5,'BTG Cartão'!$F:$F,I$4,'BTG Cartão'!$D:$D,"saída")),0) | J5: =IFERROR(-(SUMIFS('Itaú CC'!$C:$C,'Itaú CC'!$E:$E,$A5,'Itaú CC'!$F:$F,J$4,'Itaú CC'!$D:$D,"saída")+SUMIFS('Itaú Cartão'!$C:$C,'Itaú Cartão'!$E:$E,$A5,'Itaú Cartão'!$F:$F,J$4,'Itaú Cartão'!$D:$D,"saída")+SUMIFS('BTG Cartão'!$C:$C,'BTG Cartão'!$E:$E,$A5,'BTG Cartão'!$F:$F,J$4,'BTG Cartão'!$D:$D,"saída")),0) | K5: =SUM(B5:J5)
A6: Aluguel | B6: =IFERROR(-(SUMIFS('Itaú CC'!$C:$C,'Itaú CC'!$E:$E,$A6,'Itaú CC'!$F:$F,B$4,'Itaú CC'!$D:$D,"saída")+SUMIFS('Itaú Cartão'!$C:$C,'Itaú Cartão'!$E:$E,$A6,'Itaú Cartão'!$F:$F,B$4,'Itaú Cartão'!$D:$D,"saída")+SUMIFS('BTG Cartão'!$C:$C,'BTG Cartão'!$E:$E,$A6,'BTG Cartão'!$F:$F,B$4,'BTG Cartão'!$D:$D,"saída")),0) | C6: =IFERROR(-(SUMIFS('Itaú CC'!$C:$C,'Itaú CC'!$E:$E,$A6,'Itaú CC'!$F:$F,C$4,'Itaú CC'!$D:$D,"saída")+SUMIFS('Itaú Cartão'!$C:$C,'Itaú Cartão'!$E:$E,$A6,'Itaú Cartão'!$F:$F,C$4,'Itaú Cartão'!$D:$D,"saída")+SUMIFS('BTG Cartão'!$C:$C,'BTG Cartão'!$E:$E,$A6,'BTG Cartão'!$F:$F,C$4,'BTG Cartão'!$D:$D,"saída")),0) | D6: =IFERROR(-(SUMIFS('Itaú CC'!$C:$C,'Itaú CC'!$E:$E,$A6,'Itaú CC'!$F:$F,D$4,'Itaú CC'!$D:$D,"saída")+SUMIFS('Itaú Cartão'!$C:$C,'Itaú Cartão'!$E:$E,$A6,'Itaú Cartão'!$F:$F,D$4,'Itaú Cartão'!$D:$D,"saída")+SUMIFS('BTG Cartão'!$C:$C,'BTG Cartão'!$E:$E,$A6,'BTG Cartão'!$F:$F,D$4,'BTG Cartão'!$D:$D,"saída")),0) | E6: =IFERROR(-(SUMIFS('Itaú CC'!$C:$C,'Itaú CC'!$E:$E,$A6,'Itaú CC'!$F:$F,E$4,'Itaú CC'!$D:$D,"saída")+SUMIFS('Itaú Cartão'!$C:$C,'Itaú Cartão'!$E:$E,$A6,'Itaú Cartão'!$F:$F,E$4,'Itaú Cartão'!$D:$D,"saída")+SUMIFS('BTG Cartão'!$C:$C,'BTG Cartão'!$E:$E,$A6,'BTG Cartão'!$F:$F,E$4,'BTG Cartão'!$D:$D,"saída")),0) | F6: =IFERROR(-(SUMIFS('Itaú CC'!$C:$C,'Itaú CC'!$E:$E,$A6,'Itaú CC'!$F:$F,F$4,'Itaú CC'!$D:$D,"saída")+SUMIFS('Itaú Cartão'!$C:$C,'Itaú Cartão'!$E:$E,$A6,'Itaú Cartão'!$F:$F,F$4,'Itaú Cartão'!$D:$D,"saída")+SUMIFS('BTG Cartão'!$C:$C,'BTG Cartão'!$E:$E,$A6,'BTG Cartão'!$F:$F,F$4,'BTG Cartão'!$D:$D,"saída")),0) | G6: =IFERROR(-(SUMIFS('Itaú CC'!$C:$C,'Itaú CC'!$E:$E,$A6,'Itaú CC'!$F:$F,G$4,'Itaú CC'!$D:$D,"saída")+SUMIFS('Itaú Cartão'!$C:$C,'Itaú Cartão'!$E:$E,$A6,'Itaú Cartão'!$F:$F,G$4,'Itaú Cartão'!$D:$D,"saída")+SUMIFS('BTG Cartão'!$C:$C,'BTG Cartão'!$E:$E,$A6,'BTG Cartão'!$F:$F,G$4,'BTG Cartão'!$D:$D,"saída")),0) | H6: =IFERROR(-(SUMIFS('Itaú CC'!$C:$C,'Itaú CC'!$E:$E,$A6,'Itaú CC'!$F:$F,H$4,'Itaú CC'!$D:$D,"saída")+SUMIFS('Itaú Cartão'!$C:$C,'Itaú Cartão'!$E:$E,$A6,'Itaú Cartão'!$F:$F,H$4,'Itaú Cartão'!$D:$D,"saída")+SUMIFS('BTG Cartão'!$C:$C,'BTG Cartão'!$E:$E,$A6,'BTG Cartão'!$F:$F,H$4,'BTG Cartão'!$D:$D,"saída")),0) | I6: =IFERROR(-(SUMIFS('Itaú CC'!$C:$C,'Itaú CC'!$E:$E,$A6,'Itaú CC'!$F:$F,I$4,'Itaú CC'!$D:$D,"saída")+SUMIFS('Itaú Cartão'!$C:$C,'Itaú Cartão'!$E:$E,$A6,'Itaú Cartão'!$F:$F,I$4,'Itaú Cartão'!$D:$D,"saída")+SUMIFS('BTG Cartão'!$C:$C,'BTG Cartão'!$E:$E,$A6,'BTG Cartão'!$F:$F,I$4,'BTG Cartão'!$D:$D,"saída")),0) | J6: =IFERROR(-(SUMIFS('Itaú CC'!$C:$C,'Itaú CC'!$E:$E,$A6,'Itaú CC'!$F:$F,J$4,'Itaú CC'!$D:$D,"saída")+SUMIFS('Itaú Cartão'!$C:$C,'Itaú Cartão'!$E:$E,$A6,'Itaú Cartão'!$F:$F,J$4,'Itaú Cartão'!$D:$D,"saída")+SUMIFS('BTG Cartão'!$C:$C,'BTG Cartão'!$E:$E,$A6,'BTG Cartão'!$F:$F,J$4,'BTG Cartão'!$D:$D,"saída")),0) | K6: =SUM(B6:J6)
A7: Aplicação CDB | B7: =IFERROR(-(SUMIFS('Itaú CC'!$C:$C,'Itaú CC'!$E:$E,$A7,'Itaú CC'!$F:$F,B$4,'Itaú CC'!$D:$D,"saída")+SUMIFS('Itaú Cartão'!$C:$C,'Itaú Cartão'!$E:$E,$A7,'Itaú Cartão'!$F:$F,B$4,'Itaú Cartão'!$D:$D,"saída")+SUMIFS('BTG Cartão'!$C:$C,'BTG Cartão'!$E:$E,$A7,'BTG Cartão'!$F:$F,B$4,'BTG Cartão'!$D:$D,"saída")),0) | C7: =IFERROR(-(SUMIFS('Itaú CC'!$C:$C,'Itaú CC'!$E:$E,$A7,'Itaú CC'!$F:$F,C$4,'Itaú CC'!$D:$D,"saída")+SUMIFS('Itaú Cartão'!$C:$C,'Itaú Cartão'!$E:$E,$A7,'Itaú Cartão'!$F:$F,C$4,'Itaú Cartão'!$D:$D,"saída")+SUMIFS('BTG Cartão'!$C:$C,'BTG Cartão'!$E:$E,$A7,'BTG Cartão'!$F:$F,C$4,'BTG Cartão'!$D:$D,"saída")),0) | D7: =IFERROR(-(SUMIFS('Itaú CC'!$C:$C,'Itaú CC'!$E:$E,$A7,'Itaú CC'!$F:$F,D$4,'Itaú CC'!$D:$D,"saída")+SUMIFS('Itaú Cartão'!$C:$C,'Itaú Cartão'!$E:$E,$A7,'Itaú Cartão'!$F:$F,D$4,'Itaú Cartão'!$D:$D,"saída")+SUMIFS('BTG Cartão'!$C:$C,'BTG Cartão'!$E:$E,$A7,'BTG Cartão'!$F:$F,D$4,'BTG Cartão'!$D:$D,"saída")),0) | E7: =IFERROR(-(SUMIFS('Itaú CC'!$C:$C,'Itaú CC'!$E:$E,$A7,'Itaú CC'!$F:$F,E$4,'Itaú CC'!$D:$D,"saída")+SUMIFS('Itaú Cartão'!$C:$C,'Itaú Cartão'!$E:$E,$A7,'Itaú Cartão'!$F:$F,E$4,'Itaú Cartão'!$D:$D,"saída")+SUMIFS('BTG Cartão'!$C:$C,'BTG Cartão'!$E:$E,$A7,'BTG Cartão'!$F:$F,E$4,'BTG Cartão'!$D:$D,"saída")),0) | F7: =IFERROR(-(SUMIFS('Itaú CC'!$C:$C,'Itaú CC'!$E:$E,$A7,'Itaú CC'!$F:$F,F$4,'Itaú CC'!$D:$D,"saída")+SUMIFS('Itaú Cartão'!$C:$C,'Itaú Cartão'!$E:$E,$A7,'Itaú Cartão'!$F:$F,F$4,'Itaú Cartão'!$D:$D,"saída")+SUMIFS('BTG Cartão'!$C:$C,'BTG Cartão'!$E:$E,$A7,'BTG Cartão'!$F:$F,F$4,'BTG Cartão'!$D:$D,"saída")),0) | G7: =IFERROR(-(SUMIFS('Itaú CC'!$C:$C,'Itaú CC'!$E:$E,$A7,'Itaú CC'!$F:$F,G$4,'Itaú CC'!$D:$D,"saída")+SUMIFS('Itaú Cartão'!$C:$C,'Itaú Cartão'!$E:$E,$A7,'Itaú Cartão'!$F:$F,G$4,'Itaú Cartão'!$D:$D,"saída")+SUMIFS('BTG Cartão'!$C:$C,'BTG Cartão'!$E:$E,$A7,'BTG Cartão'!$F:$F,G$4,'BTG Cartão'!$D:$D,"saída")),0) | H7: =IFERROR(-(SUMIFS('Itaú CC'!$C:$C,'Itaú CC'!$E:$E,$A7,'Itaú CC'!$F:$F,H$4,'Itaú CC'!$D:$D,"saída")+SUMIFS('Itaú Cartão'!$C:$C,'Itaú Cartão'!$E:$E,$A7,'Itaú Cartão'!$F:$F,H$4,'Itaú Cartão'!$D:$D,"saída")+SUMIFS('BTG Cartão'!$C:$C,'BTG Cartão'!$E:$E,$A7,'BTG Cartão'!$F:$F,H$4,'BTG Cartão'!$D:$D,"saída")),0) | I7: =IFERROR(-(SUMIFS('Itaú CC'!$C:$C,'Itaú CC'!$E:$E,$A7,'Itaú CC'!$F:$F,I$4,'Itaú CC'!$D:$D,"saída")+SUMIFS('Itaú Cartão'!$C:$C,'Itaú Cartão'!$E:$E,$A7,'Itaú Cartão'!$F:$F,I$4,'Itaú Cartão'!$D:$D,"saída")+SUMIFS('BTG Cartão'!$C:$C,'BTG Cartão'!$E:$E,$A7,'BTG Cartão'!$F:$F,I$4,'BTG Cartão'!$D:$D,"saída")),0) | J7: =IFERROR(-(SUMIFS('Itaú CC'!$C:$C,'Itaú CC'!$E:$E,$A7,'Itaú CC'!$F:$F,J$4,'Itaú CC'!$D:$D,"saída")+SUMIFS('Itaú Cartão'!$C:$C,'Itaú Cartão'!$E:$E,$A7,'Itaú Cartão'!$F:$F,J$4,'Itaú Cartão'!$D:$D,"saída")+SUMIFS('BTG Cartão'!$C:$C,'BTG Cartão'!$E:$E,$A7,'BTG Cartão'!$F:$F,J$4,'BTG Cartão'!$D:$D,"saída")),0) | K7: =SUM(B7:J7)
A8: Aplicação LCA | B8: =IFERROR(-(SUMIFS('Itaú CC'!$C:$C,'Itaú CC'!$E:$E,$A8,'Itaú CC'!$F:$F,B$4,'Itaú CC'!$D:$D,"saída")+SUMIFS('Itaú Cartão'!$C:$C,'Itaú Cartão'!$E:$E,$A8,'Itaú Cartão'!$F:$F,B$4,'Itaú Cartão'!$D:$D,"saída")+SUMIFS('BTG Cartão'!$C:$C,'BTG Cartão'!$E:$E,$A8,'BTG Cartão'!$F:$F,B$4,'BTG Cartão'!$D:$D,"saída")),0) | C8: =IFERROR(-(SUMIFS('Itaú CC'!$C:$C,'Itaú CC'!$E:$E,$A8,'Itaú CC'!$F:$F,C$4,'Itaú CC'!$D:$D,"saída")+SUMIFS('Itaú Cartão'!$C:$C,'Itaú Cartão'!$E:$E,$A8,'Itaú Cartão'!$F:$F,C$4,'Itaú Cartão'!$D:$D,"saída")+SUMIFS('BTG Cartão'!$C:$C,'BTG Cartão'!$E:$E,$A8,'BTG Cartão'!$F:$F,C$4,'BTG Cartão'!$D:$D,"saída")),0) | D8: =IFERROR(-(SUMIFS('Itaú CC'!$C:$C,'Itaú CC'!$E:$E,$A8,'Itaú CC'!$F:$F,D$4,'Itaú CC'!$D:$D,"saída")+SUMIFS('Itaú Cartão'!$C:$C,'Itaú Cartão'!$E:$E,$A8,'Itaú Cartão'!$F:$F,D$4,'Itaú Cartão'!$D:$D,"saída")+SUMIFS('BTG Cartão'!$C:$C,'BTG Cartão'!$E:$E,$A8,'BTG Cartão'!$F:$F,D$4,'BTG Cartão'!$D:$D,"saída")),0) | E8: =IFERROR(-(SUMIFS('Itaú CC'!$C:$C,'Itaú CC'!$E:$E,$A8,'Itaú CC'!$F:$F,E$4,'Itaú CC'!$D:$D,"saída")+SUMIFS('Itaú Cartão'!$C:$C,'Itaú Cartão'!$E:$E,$A8,'Itaú Cartão'!$F:$F,E$4,'Itaú Cartão'!$D:$D,"saída")+SUMIFS('BTG Cartão'!$C:$C,'BTG Cartão'!$E:$E,$A8,'BTG Cartão'!$F:$F,E$4,'BTG Cartão'!$D:$D,"saída")),0) | F8: =IFERROR(-(SUMIFS('Itaú CC'!$C:$C,'Itaú CC'!$E:$E,$A8,'Itaú CC'!$F:$F,F$4,'Itaú CC'!$D:$D,"saída")+SUMIFS('Itaú Cartão'!$C:$C,'Itaú Cartão'!$E:$E,$A8,'Itaú Cartão'!$F:$F,F$4,'Itaú Cartão'!$D:$D,"saída")+SUMIFS('BTG Cartão'!$C:$C,'BTG Cartão'!$E:$E,$A8,'BTG Cartão'!$F:$F,F$4,'BTG Cartão'!$D:$D,"saída")),0) | G8: =IFERROR(-(SUMIFS('Itaú CC'!$C:$C,'Itaú CC'!$E:$E,$A8,'Itaú CC'!$F:$F,G$4,'Itaú CC'!$D:$D,"saída")+SUMIFS('Itaú Cartão'!$C:$C,'Itaú Cartão'!$E:$E,$A8,'Itaú Cartão'!$F:$F,G$4,'Itaú Cartão'!$D:$D,"saída")+SUMIFS('BTG Cartão'!$C:$C,'BTG Cartão'!$E:$E,$A8,'BTG Cartão'!$F:$F,G$4,'BTG Cartão'!$D:$D,"saída")),0) | H8: =IFERROR(-(SUMIFS('Itaú CC'!$C:$C,'Itaú CC'!$E:$E,$A8,'Itaú CC'!$F:$F,H$4,'Itaú CC'!$D:$D,"saída")+SUMIFS('Itaú Cartão'!$C:$C,'Itaú Cartão'!$E:$E,$A8,'Itaú Cartão'!$F:$F,H$4,'Itaú Cartão'!$D:$D,"saída")+SUMIFS('BTG Cartão'!$C:$C,'BTG Cartão'!$E:$E,$A8,'BTG Cartão'!$F:$F,H$4,'BTG Cartão'!$D:$D,"saída")),0) | I8: =IFERROR(-(SUMIFS('Itaú CC'!$C:$C,'Itaú CC'!$E:$E,$A8,'Itaú CC'!$F:$F,I$4,'Itaú CC'!$D:$D,"saída")+SUMIFS('Itaú Cartão'!$C:$C,'Itaú Cartão'!$E:$E,$A8,'Itaú Cartão'!$F:$F,I$4,'Itaú Cartão'!$D:$D,"saída")+SUMIFS('BTG Cartão'!$C:$C,'BTG Cartão'!$E:$E,$A8,'BTG Cartão'!$F:$F,I$4,'BTG Cartão'!$D:$D,"saída")),0) | J8: =IFERROR(-(SUMIFS('Itaú CC'!$C:$C,'Itaú CC'!$E:$E,$A8,'Itaú CC'!$F:$F,J$4,'Itaú CC'!$D:$D,"saída")+SUMIFS('Itaú Cartão'!$C:$C,'Itaú Cartão'!$E:$E,$A8,'Itaú Cartão'!$F:$F,J$4,'Itaú Cartão'!$D:$D,"saída")+SUMIFS('BTG Cartão'!$C:$C,'BTG Cartão'!$E:$E,$A8,'BTG Cartão'!$F:$F,J$4,'BTG Cartão'!$D:$D,"saída")),0) | K8: =SUM(B8:J8)
A9: Clube ECP | B9: =IFERROR(-(SUMIFS('Itaú CC'!$C:$C,'Itaú CC'!$E:$E,$A9,'Itaú CC'!$F:$F,B$4,'Itaú CC'!$D:$D,"saída")+SUMIFS('Itaú Cartão'!$C:$C,'Itaú Cartão'!$E:$E,$A9,'Itaú Cartão'!$F:$F,B$4,'Itaú Cartão'!$D:$D,"saída")+SUMIFS('BTG Cartão'!$C:$C,'BTG Cartão'!$E:$E,$A9,'BTG Cartão'!$F:$F,B$4,'BTG Cartão'!$D:$D,"saída")),0) | C9: =IFERROR(-(SUMIFS('Itaú CC'!$C:$C,'Itaú CC'!$E:$E,$A9,'Itaú CC'!$F:$F,C$4,'Itaú CC'!$D:$D,"saída")+SUMIFS('Itaú Cartão'!$C:$C,'Itaú Cartão'!$E:$E,$A9,'Itaú Cartão'!$F:$F,C$4,'Itaú Cartão'!$D:$D,"saída")+SUMIFS('BTG Cartão'!$C:$C,'BTG Cartão'!$E:$E,$A9,'BTG Cartão'!$F:$F,C$4,'BTG Cartão'!$D:$D,"saída")),0) | D9: =IFERROR(-(SUMIFS('Itaú CC'!$C:$C,'Itaú CC'!$E:$E,$A9,'Itaú CC'!$F:$F,D$4,'Itaú CC'!$D:$D,"saída")+SUMIFS('Itaú Cartão'!$C:$C,'Itaú Cartão'!$E:$E,$A9,'Itaú Cartão'!$F:$F,D$4,'Itaú Cartão'!$D:$D,"saída")+SUMIFS('BTG Cartão'!$C:$C,'BTG Cartão'!$E:$E,$A9,'BTG Cartão'!$F:$F,D$4,'BTG Cartão'!$D:$D,"saída")),0) | E9: =IFERROR(-(SUMIFS('Itaú CC'!$C:$C,'Itaú CC'!$E:$E,$A9,'Itaú CC'!$F:$F,E$4,'Itaú CC'!$D:$D,"saída")+SUMIFS('Itaú Cartão'!$C:$C,'Itaú Cartão'!$E:$E,$A9,'Itaú Cartão'!$F:$F,E$4,'Itaú Cartão'!$D:$D,"saída")+SUMIFS('BTG Cartão'!$C:$C,'BTG Cartão'!$E:$E,$A9,'BTG Cartão'!$F:$F,E$4,'BTG Cartão'!$D:$D,"saída")),0) | F9: =IFERROR(-(SUMIFS('Itaú CC'!$C:$C,'Itaú CC'!$E:$E,$A9,'Itaú CC'!$F:$F,F$4,'Itaú CC'!$D:$D,"saída")+SUMIFS('Itaú Cartão'!$C:$C,'Itaú Cartão'!$E:$E,$A9,'Itaú Cartão'!$F:$F,F$4,'Itaú Cartão'!$D:$D,"saída")+SUMIFS('BTG Cartão'!$C:$C,'BTG Cartão'!$E:$E,$A9,'BTG Cartão'!$F:$F,F$4,'BTG Cartão'!$D:$D,"saída")),0) | G9: =IFERROR(-(SUMIFS('Itaú CC'!$C:$C,'Itaú CC'!$E:$E,$A9,'Itaú CC'!$F:$F,G$4,'Itaú CC'!$D:$D,"saída")+SUMIFS('Itaú Cartão'!$C:$C,'Itaú Cartão'!$E:$E,$A9,'Itaú Cartão'!$F:$F,G$4,'Itaú Cartão'!$D:$D,"saída")+SUMIFS('BTG Cartão'!$C:$C,'BTG Cartão'!$E:$E,$A9,'BTG Cartão'!$F:$F,G$4,'BTG Cartão'!$D:$D,"saída")),0) | H9: =IFERROR(-(SUMIFS('Itaú CC'!$C:$C,'Itaú CC'!$E:$E,$A9,'Itaú CC'!$F:$F,H$4,'Itaú CC'!$D:$D,"saída")+SUMIFS('Itaú Cartão'!$C:$C,'Itaú Cartão'!$E:$E,$A9,'Itaú Cartão'!$F:$F,H$4,'Itaú Cartão'!$D:$D,"saída")+SUMIFS('BTG Cartão'!$C:$C,'BTG Cartão'!$E:$E,$A9,'BTG Cartão'!$F:$F,H$4,'BTG Cartão'!$D:$D,"saída")),0) | I9: =IFERROR(-(SUMIFS('Itaú CC'!$C:$C,'Itaú CC'!$E:$E,$A9,'Itaú CC'!$F:$F,I$4,'Itaú CC'!$D:$D,"saída")+SUMIFS('Itaú Cartão'!$C:$C,'Itaú Cartão'!$E:$E,$A9,'Itaú Cartão'!$F:$F,I$4,'Itaú Cartão'!$D:$D,"saída")+SUMIFS('BTG Cartão'!$C:$C,'BTG Cartão'!$E:$E,$A9,'BTG Cartão'!$F:$F,I$4,'BTG Cartão'!$D:$D,"saída")),0) | J9: =IFERROR(-(SUMIFS('Itaú CC'!$C:$C,'Itaú CC'!$E:$E,$A9,'Itaú CC'!$F:$F,J$4,'Itaú CC'!$D:$D,"saída")+SUMIFS('Itaú Cartão'!$C:$C,'Itaú Cartão'!$E:$E,$A9,'Itaú Cartão'!$F:$F,J$4,'Itaú Cartão'!$D:$D,"saída")+SUMIFS('BTG Cartão'!$C:$C,'BTG Cartão'!$E:$E,$A9,'BTG Cartão'!$F:$F,J$4,'BTG Cartão'!$D:$D,"saída")),0) | K9: =SUM(B9:J9)
A10: Clube Paineiras | B10: =IFERROR(-(SUMIFS('Itaú CC'!$C:$C,'Itaú CC'!$E:$E,$A10,'Itaú CC'!$F:$F,B$4,'Itaú CC'!$D:$D,"saída")+SUMIFS('Itaú Cartão'!$C:$C,'Itaú Cartão'!$E:$E,$A10,'Itaú Cartão'!$F:$F,B$4,'Itaú Cartão'!$D:$D,"saída")+SUMIFS('BTG Cartão'!$C:$C,'BTG Cartão'!$E:$E,$A10,'BTG Cartão'!$F:$F,B$4,'BTG Cartão'!$D:$D,"saída")),0) | C10: =IFERROR(-(SUMIFS('Itaú CC'!$C:$C,'Itaú CC'!$E:$E,$A10,'Itaú CC'!$F:$F,C$4,'Itaú CC'!$D:$D,"saída")+SUMIFS('Itaú Cartão'!$C:$C,'Itaú Cartão'!$E:$E,$A10,'Itaú Cartão'!$F:$F,C$4,'Itaú Cartão'!$D:$D,"saída")+SUMIFS('BTG Cartão'!$C:$C,'BTG Cartão'!$E:$E,$A10,'BTG Cartão'!$F:$F,C$4,'BTG Cartão'!$D:$D,"saída")),0) | D10: =IFERROR(-(SUMIFS('Itaú CC'!$C:$C,'Itaú CC'!$E:$E,$A10,'Itaú CC'!$F:$F,D$4,'Itaú CC'!$D:$D,"saída")+SUMIFS('Itaú Cartão'!$C:$C,'Itaú Cartão'!$E:$E,$A10,'Itaú Cartão'!$F:$F,D$4,'Itaú Cartão'!$D:$D,"saída")+SUMIFS('BTG Cartão'!$C:$C,'BTG Cartão'!$E:$E,$A10,'BTG Cartão'!$F:$F,D$4,'BTG Cartão'!$D:$D,"saída")),0) | E10: =IFERROR(-(SUMIFS('Itaú CC'!$C:$C,'Itaú CC'!$E:$E,$A10,'Itaú CC'!$F:$F,E$4,'Itaú CC'!$D:$D,"saída")+SUMIFS('Itaú Cartão'!$C:$C,'Itaú Cartão'!$E:$E,$A10,'Itaú Cartão'!$F:$F,E$4,'Itaú Cartão'!$D:$D,"saída")+SUMIFS('BTG Cartão'!$C:$C,'BTG Cartão'!$E:$E,$A10,'BTG Cartão'!$F:$F,E$4,'BTG Cartão'!$D:$D,"saída")),0) | F10: =IFERROR(-(SUMIFS('Itaú CC'!$C:$C,'Itaú CC'!$E:$E,$A10,'Itaú CC'!$F:$F,F$4,'Itaú CC'!$D:$D,"saída")+SUMIFS('Itaú Cartão'!$C:$C,'Itaú Cartão'!$E:$E,$A10,'Itaú Cartão'!$F:$F,F$4,'Itaú Cartão'!$D:$D,"saída")+SUMIFS('BTG Cartão'!$C:$C,'BTG Cartão'!$E:$E,$A10,'BTG Cartão'!$F:$F,F$4,'BTG Cartão'!$D:$D,"saída")),0) | G10: =IFERROR(-(SUMIFS('Itaú CC'!$C:$C,'Itaú CC'!$E:$E,$A10,'Itaú CC'!$F:$F,G$4,'Itaú CC'!$D:$D,"saída")+SUMIFS('Itaú Cartão'!$C:$C,'Itaú Cartão'!$E:$E,$A10,'Itaú Cartão'!$F:$F,G$4,'Itaú Cartão'!$D:$D,"saída")+SUMIFS('BTG Cartão'!$C:$C,'BTG Cartão'!$E:$E,$A10,'BTG Cartão'!$F:$F,G$4,'BTG Cartão'!$D:$D,"saída")),0) | H10: =IFERROR(-(SUMIFS('Itaú CC'!$C:$C,'Itaú CC'!$E:$E,$A10,'Itaú CC'!$F:$F,H$4,'Itaú CC'!$D:$D,"saída")+SUMIFS('Itaú Cartão'!$C:$C,'Itaú Cartão'!$E:$E,$A10,'Itaú Cartão'!$F:$F,H$4,'Itaú Cartão'!$D:$D,"saída")+SUMIFS('BTG Cartão'!$C:$C,'BTG Cartão'!$E:$E,$A10,'BTG Cartão'!$F:$F,H$4,'BTG Cartão'!$D:$D,"saída")),0) | I10: =IFERROR(-(SUMIFS('Itaú CC'!$C:$C,'Itaú CC'!$E:$E,$A10,'Itaú CC'!$F:$F,I$4,'Itaú CC'!$D:$D,"saída")+SUMIFS('Itaú Cartão'!$C:$C,'Itaú Cartão'!$E:$E,$A10,'Itaú Cartão'!$F:$F,I$4,'Itaú Cartão'!$D:$D,"saída")+SUMIFS('BTG Cartão'!$C:$C,'BTG Cartão'!$E:$E,$A10,'BTG Cartão'!$F:$F,I$4,'BTG Cartão'!$D:$D,"saída")),0) | J10: =IFERROR(-(SUMIFS('Itaú CC'!$C:$C,'Itaú CC'!$E:$E,$A10,'Itaú CC'!$F:$F,J$4,'Itaú CC'!$D:$D,"saída")+SUMIFS('Itaú Cartão'!$C:$C,'Itaú Cartão'!$E:$E,$A10,'Itaú Cartão'!$F:$F,J$4,'Itaú Cartão'!$D:$D,"saída")+SUMIFS('BTG Cartão'!$C:$C,'BTG Cartão'!$E:$E,$A10,'BTG Cartão'!$F:$F,J$4,'BTG Cartão'!$D:$D,"saída")),0) | K10: =SUM(B10:J10)
A11: Clínica Esposa | B11: =IFERROR(-(SUMIFS('Itaú CC'!$C:$C,'Itaú CC'!$E:$E,$A11,'Itaú CC'!$F:$F,B$4,'Itaú CC'!$D:$D,"saída")+SUMIFS('Itaú Cartão'!$C:$C,'Itaú Cartão'!$E:$E,$A11,'Itaú Cartão'!$F:$F,B$4,'Itaú Cartão'!$D:$D,"saída")+SUMIFS('BTG Cartão'!$C:$C,'BTG Cartão'!$E:$E,$A11,'BTG Cartão'!$F:$F,B$4,'BTG Cartão'!$D:$D,"saída")),0) | C11: =IFERROR(-(SUMIFS('Itaú CC'!$C:$C,'Itaú CC'!$E:$E,$A11,'Itaú CC'!$F:$F,C$4,'Itaú CC'!$D:$D,"saída")+SUMIFS('Itaú Cartão'!$C:$C,'Itaú Cartão'!$E:$E,$A11,'Itaú Cartão'!$F:$F,C$4,'Itaú Cartão'!$D:$D,"saída")+SUMIFS('BTG Cartão'!$C:$C,'BTG Cartão'!$E:$E,$A11,'BTG Cartão'!$F:$F,C$4,'BTG Cartão'!$D:$D,"saída")),0) | D11: =IFERROR(-(SUMIFS('Itaú CC'!$C:$C,'Itaú CC'!$E:$E,$A11,'Itaú CC'!$F:$F,D$4,'Itaú CC'!$D:$D,"saída")+SUMIFS('Itaú Cartão'!$C:$C,'Itaú Cartão'!$E:$E,$A11,'Itaú Cartão'!$F:$F,D$4,'Itaú Cartão'!$D:$D,"saída")+SUMIFS('BTG Cartão'!$C:$C,'BTG Cartão'!$E:$E,$A11,'BTG Cartão'!$F:$F,D$4,'BTG Cartão'!$D:$D,"saída")),0) | E11: =IFERROR(-(SUMIFS('Itaú CC'!$C:$C,'Itaú CC'!$E:$E,$A11,'Itaú CC'!$F:$F,E$4,'Itaú CC'!$D:$D,"saída")+SUMIFS('Itaú Cartão'!$C:$C,'Itaú Cartão'!$E:$E,$A11,'Itaú Cartão'!$F:$F,E$4,'Itaú Cartão'!$D:$D,"saída")+SUMIFS('BTG Cartão'!$C:$C,'BTG Cartão'!$E:$E,$A11,'BTG Cartão'!$F:$F,E$4,'BTG Cartão'!$D:$D,"saída")),0) | F11: =IFERROR(-(SUMIFS('Itaú CC'!$C:$C,'Itaú CC'!$E:$E,$A11,'Itaú CC'!$F:$F,F$4,'Itaú CC'!$D:$D,"saída")+SUMIFS('Itaú Cartão'!$C:$C,'Itaú Cartão'!$E:$E,$A11,'Itaú Cartão'!$F:$F,F$4,'Itaú Cartão'!$D:$D,"saída")+SUMIFS('BTG Cartão'!$C:$C,'BTG Cartão'!$E:$E,$A11,'BTG Cartão'!$F:$F,F$4,'BTG Cartão'!$D:$D,"saída")),0) | G11: =IFERROR(-(SUMIFS('Itaú CC'!$C:$C,'Itaú CC'!$E:$E,$A11,'Itaú CC'!$F:$F,G$4,'Itaú CC'!$D:$D,"saída")+SUMIFS('Itaú Cartão'!$C:$C,'Itaú Cartão'!$E:$E,$A11,'Itaú Cartão'!$F:$F,G$4,'Itaú Cartão'!$D:$D,"saída")+SUMIFS('BTG Cartão'!$C:$C,'BTG Cartão'!$E:$E,$A11,'BTG Cartão'!$F:$F,G$4,'BTG Cartão'!$D:$D,"saída")),0) | H11: =IFERROR(-(SUMIFS('Itaú CC'!$C:$C,'Itaú CC'!$E:$E,$A11,'Itaú CC'!$F:$F,H$4,'Itaú CC'!$D:$D,"saída")+SUMIFS('Itaú Cartão'!$C:$C,'Itaú Cartão'!$E:$E,$A11,'Itaú Cartão'!$F:$F,H$4,'Itaú Cartão'!$D:$D,"saída")+SUMIFS('BTG Cartão'!$C:$C,'BTG Cartão'!$E:$E,$A11,'BTG Cartão'!$F:$F,H$4,'BTG Cartão'!$D:$D,"saída")),0) | I11: =IFERROR(-(SUMIFS('Itaú CC'!$C:$C,'Itaú CC'!$E:$E,$A11,'Itaú CC'!$F:$F,I$4,'Itaú CC'!$D:$D,"saída")+SUMIFS('Itaú Cartão'!$C:$C,'Itaú Cartão'!$E:$E,$A11,'Itaú Cartão'!$F:$F,I$4,'Itaú Cartão'!$D:$D,"saída")+SUMIFS('BTG Cartão'!$C:$C,'BTG Cartão'!$E:$E,$A11,'BTG Cartão'!$F:$F,I$4,'BTG Cartão'!$D:$D,"saída")),0) | J11: =IFERROR(-(SUMIFS('Itaú CC'!$C:$C,'Itaú CC'!$E:$E,$A11,'Itaú CC'!$F:$F,J$4,'Itaú CC'!$D:$D,"saída")+SUMIFS('Itaú Cartão'!$C:$C,'Itaú Cartão'!$E:$E,$A11,'Itaú Cartão'!$F:$F,J$4,'Itaú Cartão'!$D:$D,"saída")+SUMIFS('BTG Cartão'!$C:$C,'BTG Cartão'!$E:$E,$A11,'BTG Cartão'!$F:$F,J$4,'BTG Cartão'!$D:$D,"saída")),0) | K11: =SUM(B11:J11)
A12: Combustível | B12: =IFERROR(-(SUMIFS('Itaú CC'!$C:$C,'Itaú CC'!$E:$E,$A12,'Itaú CC'!$F:$F,B$4,'Itaú CC'!$D:$D,"saída")+SUMIFS('Itaú Cartão'!$C:$C,'Itaú Cartão'!$E:$E,$A12,'Itaú Cartão'!$F:$F,B$4,'Itaú Cartão'!$D:$D,"saída")+SUMIFS('BTG Cartão'!$C:$C,'BTG Cartão'!$E:$E,$A12,'BTG Cartão'!$F:$F,B$4,'BTG Cartão'!$D:$D,"saída")),0) | C12: =IFERROR(-(SUMIFS('Itaú CC'!$C:$C,'Itaú CC'!$E:$E,$A12,'Itaú CC'!$F:$F,C$4,'Itaú CC'!$D:$D,"saída")+SUMIFS('Itaú Cartão'!$C:$C,'Itaú Cartão'!$E:$E,$A12,'Itaú Cartão'!$F:$F,C$4,'Itaú Cartão'!$D:$D,"saída")+SUMIFS('BTG Cartão'!$C:$C,'BTG Cartão'!$E:$E,$A12,'BTG Cartão'!$F:$F,C$4,'BTG Cartão'!$D:$D,"saída")),0) | D12: =IFERROR(-(SUMIFS('Itaú CC'!$C:$C,'Itaú CC'!$E:$E,$A12,'Itaú CC'!$F:$F,D$4,'Itaú CC'!$D:$D,"saída")+SUMIFS('Itaú Cartão'!$C:$C,'Itaú Cartão'!$E:$E,$A12,'Itaú Cartão'!$F:$F,D$4,'Itaú Cartão'!$D:$D,"saída")+SUMIFS('BTG Cartão'!$C:$C,'BTG Cartão'!$E:$E,$A12,'BTG Cartão'!$F:$F,D$4,'BTG Cartão'!$D:$D,"saída")),0) | E12: =IFERROR(-(SUMIFS('Itaú CC'!$C:$C,'Itaú CC'!$E:$E,$A12,'Itaú CC'!$F:$F,E$4,'Itaú CC'!$D:$D,"saída")+SUMIFS('Itaú Cartão'!$C:$C,'Itaú Cartão'!$E:$E,$A12,'Itaú Cartão'!$F:$F,E$4,'Itaú Cartão'!$D:$D,"saída")+SUMIFS('BTG Cartão'!$C:$C,'BTG Cartão'!$E:$E,$A12,'BTG Cartão'!$F:$F,E$4,'BTG Cartão'!$D:$D,"saída")),0) | F12: =IFERROR(-(SUMIFS('Itaú CC'!$C:$C,'Itaú CC'!$E:$E,$A12,'Itaú CC'!$F:$F,F$4,'Itaú CC'!$D:$D,"saída")+SUMIFS('Itaú Cartão'!$C:$C,'Itaú Cartão'!$E:$E,$A12,'Itaú Cartão'!$F:$F,F$4,'Itaú Cartão'!$D:$D,"saída")+SUMIFS('BTG Cartão'!$C:$C,'BTG Cartão'!$E:$E,$A12,'BTG Cartão'!$F:$F,F$4,'BTG Cartão'!$D:$D,"saída")),0) | G12: =IFERROR(-(SUMIFS('Itaú CC'!$C:$C,'Itaú CC'!$E:$E,$A12,'Itaú CC'!$F:$F,G$4,'Itaú CC'!$D:$D,"saída")+SUMIFS('Itaú Cartão'!$C:$C,'Itaú Cartão'!$E:$E,$A12,'Itaú Cartão'!$F:$F,G$4,'Itaú Cartão'!$D:$D,"saída")+SUMIFS('BTG Cartão'!$C:$C,'BTG Cartão'!$E:$E,$A12,'BTG Cartão'!$F:$F,G$4,'BTG Cartão'!$D:$D,"saída")),0) | H12: =IFERROR(-(SUMIFS('Itaú CC'!$C:$C,'Itaú CC'!$E:$E,$A12,'Itaú CC'!$F:$F,H$4,'Itaú CC'!$D:$D,"saída")+SUMIFS('Itaú Cartão'!$C:$C,'Itaú Cartão'!$E:$E,$A12,'Itaú Cartão'!$F:$F,H$4,'Itaú Cartão'!$D:$D,"saída")+SUMIFS('BTG Cartão'!$C:$C,'BTG Cartão'!$E:$E,$A12,'BTG Cartão'!$F:$F,H$4,'BTG Cartão'!$D:$D,"saída")),0) | I12: =IFERROR(-(SUMIFS('Itaú CC'!$C:$C,'Itaú CC'!$E:$E,$A12,'Itaú CC'!$F:$F,I$4,'Itaú CC'!$D:$D,"saída")+SUMIFS('Itaú Cartão'!$C:$C,'Itaú Cartão'!$E:$E,$A12,'Itaú Cartão'!$F:$F,I$4,'Itaú Cartão'!$D:$D,"saída")+SUMIFS('BTG Cartão'!$C:$C,'BTG Cartão'!$E:$E,$A12,'BTG Cartão'!$F:$F,I$4,'BTG Cartão'!$D:$D,"saída")),0) | J12: =IFERROR(-(SUMIFS('Itaú CC'!$C:$C,'Itaú CC'!$E:$E,$A12,'Itaú CC'!$F:$F,J$4,'Itaú CC'!$D:$D,"saída")+SUMIFS('Itaú Cartão'!$C:$C,'Itaú Cartão'!$E:$E,$A12,'Itaú Cartão'!$F:$F,J$4,'Itaú Cartão'!$D:$D,"saída")+SUMIFS('BTG Cartão'!$C:$C,'BTG Cartão'!$E:$E,$A12,'BTG Cartão'!$F:$F,J$4,'BTG Cartão'!$D:$D,"saída")),0) | K12: =SUM(B12:J12)
A13: Contabilidade | B13: =IFERROR(-(SUMIFS('Itaú CC'!$C:$C,'Itaú CC'!$E:$E,$A13,'Itaú CC'!$F:$F,B$4,'Itaú CC'!$D:$D,"saída")+SUMIFS('Itaú Cartão'!$C:$C,'Itaú Cartão'!$E:$E,$A13,'Itaú Cartão'!$F:$F,B$4,'Itaú Cartão'!$D:$D,"saída")+SUMIFS('BTG Cartão'!$C:$C,'BTG Cartão'!$E:$E,$A13,'BTG Cartão'!$F:$F,B$4,'BTG Cartão'!$D:$D,"saída")),0) | C13: =IFERROR(-(SUMIFS('Itaú CC'!$C:$C,'Itaú CC'!$E:$E,$A13,'Itaú CC'!$F:$F,C$4,'Itaú CC'!$D:$D,"saída")+SUMIFS('Itaú Cartão'!$C:$C,'Itaú Cartão'!$E:$E,$A13,'Itaú Cartão'!$F:$F,C$4,'Itaú Cartão'!$D:$D,"saída")+SUMIFS('BTG Cartão'!$C:$C,'BTG Cartão'!$E:$E,$A13,'BTG Cartão'!$F:$F,C$4,'BTG Cartão'!$D:$D,"saída")),0) | D13: =IFERROR(-(SUMIFS('Itaú CC'!$C:$C,'Itaú CC'!$E:$E,$A13,'Itaú CC'!$F:$F,D$4,'Itaú CC'!$D:$D,"saída")+SUMIFS('Itaú Cartão'!$C:$C,'Itaú Cartão'!$E:$E,$A13,'Itaú Cartão'!$F:$F,D$4,'Itaú Cartão'!$D:$D,"saída")+SUMIFS('BTG Cartão'!$C:$C,'BTG Cartão'!$E:$E,$A13,'BTG Cartão'!$F:$F,D$4,'BTG Cartão'!$D:$D,"saída")),0) | E13: =IFERROR(-(SUMIFS('Itaú CC'!$C:$C,'Itaú CC'!$E:$E,$A13,'Itaú CC'!$F:$F,E$4,'Itaú CC'!$D:$D,"saída")+SUMIFS('Itaú Cartão'!$C:$C,'Itaú Cartão'!$E:$E,$A13,'Itaú Cartão'!$F:$F,E$4,'Itaú Cartão'!$D:$D,"saída")+SUMIFS('BTG Cartão'!$C:$C,'BTG Cartão'!$E:$E,$A13,'BTG Cartão'!$F:$F,E$4,'BTG Cartão'!$D:$D,"saída")),0) | F13: =IFERROR(-(SUMIFS('Itaú CC'!$C:$C,'Itaú CC'!$E:$E,$A13,'Itaú CC'!$F:$F,F$4,'Itaú CC'!$D:$D,"saída")+SUMIFS('Itaú Cartão'!$C:$C,'Itaú Cartão'!$E:$E,$A13,'Itaú Cartão'!$F:$F,F$4,'Itaú Cartão'!$D:$D,"saída")+SUMIFS('BTG Cartão'!$C:$C,'BTG Cartão'!$E:$E,$A13,'BTG Cartão'!$F:$F,F$4,'BTG Cartão'!$D:$D,"saída")),0) | G13: =IFERROR(-(SUMIFS('Itaú CC'!$C:$C,'Itaú CC'!$E:$E,$A13,'Itaú CC'!$F:$F,G$4,'Itaú CC'!$D:$D,"saída")+SUMIFS('Itaú Cartão'!$C:$C,'Itaú Cartão'!$E:$E,$A13,'Itaú Cartão'!$F:$F,G$4,'Itaú Cartão'!$D:$D,"saída")+SUMIFS('BTG Cartão'!$C:$C,'BTG Cartão'!$E:$E,$A13,'BTG Cartão'!$F:$F,G$4,'BTG Cartão'!$D:$D,"saída")),0) | H13: =IFERROR(-(SUMIFS('Itaú CC'!$C:$C,'Itaú CC'!$E:$E,$A13,'Itaú CC'!$F:$F,H$4,'Itaú CC'!$D:$D,"saída")+SUMIFS('Itaú Cartão'!$C:$C,'Itaú Cartão'!$E:$E,$A13,'Itaú Cartão'!$F:$F,H$4,'Itaú Cartão'!$D:$D,"saída")+SUMIFS('BTG Cartão'!$C:$C,'BTG Cartão'!$E:$E,$A13,'BTG Cartão'!$F:$F,H$4,'BTG Cartão'!$D:$D,"saída")),0) | I13: =IFERROR(-(SUMIFS('Itaú CC'!$C:$C,'Itaú CC'!$E:$E,$A13,'Itaú CC'!$F:$F,I$4,'Itaú CC'!$D:$D,"saída")+SUMIFS('Itaú Cartão'!$C:$C,'Itaú Cartão'!$E:$E,$A13,'Itaú Cartão'!$F:$F,I$4,'Itaú Cartão'!$D:$D,"saída")+SUMIFS('BTG Cartão'!$C:$C,'BTG Cartão'!$E:$E,$A13,'BTG Cartão'!$F:$F,I$4,'BTG Cartão'!$D:$D,"saída")),0) | J13: =IFERROR(-(SUMIFS('Itaú CC'!$C:$C,'Itaú CC'!$E:$E,$A13,'Itaú CC'!$F:$F,J$4,'Itaú CC'!$D:$D,"saída")+SUMIFS('Itaú Cartão'!$C:$C,'Itaú Cartão'!$E:$E,$A13,'Itaú Cartão'!$F:$F,J$4,'Itaú Cartão'!$D:$D,"saída")+SUMIFS('BTG Cartão'!$C:$C,'BTG Cartão'!$E:$E,$A13,'BTG Cartão'!$F:$F,J$4,'BTG Cartão'!$D:$D,"saída")),0) | K13: =SUM(B13:J13)
A14: Cripto | B14: =IFERROR(-(SUMIFS('Itaú CC'!$C:$C,'Itaú CC'!$E:$E,$A14,'Itaú CC'!$F:$F,B$4,'Itaú CC'!$D:$D,"saída")+SUMIFS('Itaú Cartão'!$C:$C,'Itaú Cartão'!$E:$E,$A14,'Itaú Cartão'!$F:$F,B$4,'Itaú Cartão'!$D:$D,"saída")+SUMIFS('BTG Cartão'!$C:$C,'BTG Cartão'!$E:$E,$A14,'BTG Cartão'!$F:$F,B$4,'BTG Cartão'!$D:$D,"saída")),0) | C14: =IFERROR(-(SUMIFS('Itaú CC'!$C:$C,'Itaú CC'!$E:$E,$A14,'Itaú CC'!$F:$F,C$4,'Itaú CC'!$D:$D,"saída")+SUMIFS('Itaú Cartão'!$C:$C,'Itaú Cartão'!$E:$E,$A14,'Itaú Cartão'!$F:$F,C$4,'Itaú Cartão'!$D:$D,"saída")+SUMIFS('BTG Cartão'!$C:$C,'BTG Cartão'!$E:$E,$A14,'BTG Cartão'!$F:$F,C$4,'BTG Cartão'!$D:$D,"saída")),0) | D14: =IFERROR(-(SUMIFS('Itaú CC'!$C:$C,'Itaú CC'!$E:$E,$A14,'Itaú CC'!$F:$F,D$4,'Itaú CC'!$D:$D,"saída")+SUMIFS('Itaú Cartão'!$C:$C,'Itaú Cartão'!$E:$E,$A14,'Itaú Cartão'!$F:$F,D$4,'Itaú Cartão'!$D:$D,"saída")+SUMIFS('BTG Cartão'!$C:$C,'BTG Cartão'!$E:$E,$A14,'BTG Cartão'!$F:$F,D$4,'BTG Cartão'!$D:$D,"saída")),0) | E14: =IFERROR(-(SUMIFS('Itaú CC'!$C:$C,'Itaú CC'!$E:$E,$A14,'Itaú CC'!$F:$F,E$4,'Itaú CC'!$D:$D,"saída")+SUMIFS('Itaú Cartão'!$C:$C,'Itaú Cartão'!$E:$E,$A14,'Itaú Cartão'!$F:$F,E$4,'Itaú Cartão'!$D:$D,"saída")+SUMIFS('BTG Cartão'!$C:$C,'BTG Cartão'!$E:$E,$A14,'BTG Cartão'!$F:$F,E$4,'BTG Cartão'!$D:$D,"saída")),0) | F14: =IFERROR(-(SUMIFS('Itaú CC'!$C:$C,'Itaú CC'!$E:$E,$A14,'Itaú CC'!$F:$F,F$4,'Itaú CC'!$D:$D,"saída")+SUMIFS('Itaú Cartão'!$C:$C,'Itaú Cartão'!$E:$E,$A14,'Itaú Cartão'!$F:$F,F$4,'Itaú Cartão'!$D:$D,"saída")+SUMIFS('BTG Cartão'!$C:$C,'BTG Cartão'!$E:$E,$A14,'BTG Cartão'!$F:$F,F$4,'BTG Cartão'!$D:$D,"saída")),0) | G14: =IFERROR(-(SUMIFS('Itaú CC'!$C:$C,'Itaú CC'!$E:$E,$A14,'Itaú CC'!$F:$F,G$4,'Itaú CC'!$D:$D,"saída")+SUMIFS('Itaú Cartão'!$C:$C,'Itaú Cartão'!$E:$E,$A14,'Itaú Cartão'!$F:$F,G$4,'Itaú Cartão'!$D:$D,"saída")+SUMIFS('BTG Cartão'!$C:$C,'BTG Cartão'!$E:$E,$A14,'BTG Cartão'!$F:$F,G$4,'BTG Cartão'!$D:$D,"saída")),0) | H14: =IFERROR(-(SUMIFS('Itaú CC'!$C:$C,'Itaú CC'!$E:$E,$A14,'Itaú CC'!$F:$F,H$4,'Itaú CC'!$D:$D,"saída")+SUMIFS('Itaú Cartão'!$C:$C,'Itaú Cartão'!$E:$E,$A14,'Itaú Cartão'!$F:$F,H$4,'Itaú Cartão'!$D:$D,"saída")+SUMIFS('BTG Cartão'!$C:$C,'BTG Cartão'!$E:$E,$A14,'BTG Cartão'!$F:$F,H$4,'BTG Cartão'!$D:$D,"saída")),0) | I14: =IFERROR(-(SUMIFS('Itaú CC'!$C:$C,'Itaú CC'!$E:$E,$A14,'Itaú CC'!$F:$F,I$4,'Itaú CC'!$D:$D,"saída")+SUMIFS('Itaú Cartão'!$C:$C,'Itaú Cartão'!$E:$E,$A14,'Itaú Cartão'!$F:$F,I$4,'Itaú Cartão'!$D:$D,"saída")+SUMIFS('BTG Cartão'!$C:$C,'BTG Cartão'!$E:$E,$A14,'BTG Cartão'!$F:$F,I$4,'BTG Cartão'!$D:$D,"saída")),0) | J14: =IFERROR(-(SUMIFS('Itaú CC'!$C:$C,'Itaú CC'!$E:$E,$A14,'Itaú CC'!$F:$F,J$4,'Itaú CC'!$D:$D,"saída")+SUMIFS('Itaú Cartão'!$C:$C,'Itaú Cartão'!$E:$E,$A14,'Itaú Cartão'!$F:$F,J$4,'Itaú Cartão'!$D:$D,"saída")+SUMIFS('BTG Cartão'!$C:$C,'BTG Cartão'!$E:$E,$A14,'BTG Cartão'!$F:$F,J$4,'BTG Cartão'!$D:$D,"saída")),0) | K14: =SUM(B14:J14)
A15: Educação | B15: =IFERROR(-(SUMIFS('Itaú CC'!$C:$C,'Itaú CC'!$E:$E,$A15,'Itaú CC'!$F:$F,B$4,'Itaú CC'!$D:$D,"saída")+SUMIFS('Itaú Cartão'!$C:$C,'Itaú Cartão'!$E:$E,$A15,'Itaú Cartão'!$F:$F,B$4,'Itaú Cartão'!$D:$D,"saída")+SUMIFS('BTG Cartão'!$C:$C,'BTG Cartão'!$E:$E,$A15,'BTG Cartão'!$F:$F,B$4,'BTG Cartão'!$D:$D,"saída")),0) | C15: =IFERROR(-(SUMIFS('Itaú CC'!$C:$C,'Itaú CC'!$E:$E,$A15,'Itaú CC'!$F:$F,C$4,'Itaú CC'!$D:$D,"saída")+SUMIFS('Itaú Cartão'!$C:$C,'Itaú Cartão'!$E:$E,$A15,'Itaú Cartão'!$F:$F,C$4,'Itaú Cartão'!$D:$D,"saída")+SUMIFS('BTG Cartão'!$C:$C,'BTG Cartão'!$E:$E,$A15,'BTG Cartão'!$F:$F,C$4,'BTG Cartão'!$D:$D,"saída")),0) | D15: =IFERROR(-(SUMIFS('Itaú CC'!$C:$C,'Itaú CC'!$E:$E,$A15,'Itaú CC'!$F:$F,D$4,'Itaú CC'!$D:$D,"saída")+SUMIFS('Itaú Cartão'!$C:$C,'Itaú Cartão'!$E:$E,$A15,'Itaú Cartão'!$F:$F,D$4,'Itaú Cartão'!$D:$D,"saída")+SUMIFS('BTG Cartão'!$C:$C,'BTG Cartão'!$E:$E,$A15,'BTG Cartão'!$F:$F,D$4,'BTG Cartão'!$D:$D,"saída")),0) | E15: =IFERROR(-(SUMIFS('Itaú CC'!$C:$C,'Itaú CC'!$E:$E,$A15,'Itaú CC'!$F:$F,E$4,'Itaú CC'!$D:$D,"saída")+SUMIFS('Itaú Cartão'!$C:$C,'Itaú Cartão'!$E:$E,$A15,'Itaú Cartão'!$F:$F,E$4,'Itaú Cartão'!$D:$D,"saída")+SUMIFS('BTG Cartão'!$C:$C,'BTG Cartão'!$E:$E,$A15,'BTG Cartão'!$F:$F,E$4,'BTG Cartão'!$D:$D,"saída")),0) | F15: =IFERROR(-(SUMIFS('Itaú CC'!$C:$C,'Itaú CC'!$E:$E,$A15,'Itaú CC'!$F:$F,F$4,'Itaú CC'!$D:$D,"saída")+SUMIFS('Itaú Cartão'!$C:$C,'Itaú Cartão'!$E:$E,$A15,'Itaú Cartão'!$F:$F,F$4,'Itaú Cartão'!$D:$D,"saída")+SUMIFS('BTG Cartão'!$C:$C,'BTG Cartão'!$E:$E,$A15,'BTG Cartão'!$F:$F,F$4,'BTG Cartão'!$D:$D,"saída")),0) | G15: =IFERROR(-(SUMIFS('Itaú CC'!$C:$C,'Itaú CC'!$E:$E,$A15,'Itaú CC'!$F:$F,G$4,'Itaú CC'!$D:$D,"saída")+SUMIFS('Itaú Cartão'!$C:$C,'Itaú Cartão'!$E:$E,$A15,'Itaú Cartão'!$F:$F,G$4,'Itaú Cartão'!$D:$D,"saída")+SUMIFS('BTG Cartão'!$C:$C,'BTG Cartão'!$E:$E,$A15,'BTG Cartão'!$F:$F,G$4,'BTG Cartão'!$D:$D,"saída")),0) | H15: =IFERROR(-(SUMIFS('Itaú CC'!$C:$C,'Itaú CC'!$E:$E,$A15,'Itaú CC'!$F:$F,H$4,'Itaú CC'!$D:$D,"saída")+SUMIFS('Itaú Cartão'!$C:$C,'Itaú Cartão'!$E:$E,$A15,'Itaú Cartão'!$F:$F,H$4,'Itaú Cartão'!$D:$D,"saída")+SUMIFS('BTG Cartão'!$C:$C,'BTG Cartão'!$E:$E,$A15,'BTG Cartão'!$F:$F,H$4,'BTG Cartão'!$D:$D,"saída")),0) | I15: =IFERROR(-(SUMIFS('Itaú CC'!$C:$C,'Itaú CC'!$E:$E,$A15,'Itaú CC'!$F:$F,I$4,'Itaú CC'!$D:$D,"saída")+SUMIFS('Itaú Cartão'!$C:$C,'Itaú Cartão'!$E:$E,$A15,'Itaú Cartão'!$F:$F,I$4,'Itaú Cartão'!$D:$D,"saída")+SUMIFS('BTG Cartão'!$C:$C,'BTG Cartão'!$E:$E,$A15,'BTG Cartão'!$F:$F,I$4,'BTG Cartão'!$D:$D,"saída")),0) | J15: =IFERROR(-(SUMIFS('Itaú CC'!$C:$C,'Itaú CC'!$E:$E,$A15,'Itaú CC'!$F:$F,J$4,'Itaú CC'!$D:$D,"saída")+SUMIFS('Itaú Cartão'!$C:$C,'Itaú Cartão'!$E:$E,$A15,'Itaú Cartão'!$F:$F,J$4,'Itaú Cartão'!$D:$D,"saída")+SUMIFS('BTG Cartão'!$C:$C,'BTG Cartão'!$E:$E,$A15,'BTG Cartão'!$F:$F,J$4,'BTG Cartão'!$D:$D,"saída")),0) | K15: =SUM(B15:J15)
A16: Fatura Cartão | B16: =IFERROR(-(SUMIFS('Itaú CC'!$C:$C,'Itaú CC'!$E:$E,$A16,'Itaú CC'!$F:$F,B$4,'Itaú CC'!$D:$D,"saída")+SUMIFS('Itaú Cartão'!$C:$C,'Itaú Cartão'!$E:$E,$A16,'Itaú Cartão'!$F:$F,B$4,'Itaú Cartão'!$D:$D,"saída")+SUMIFS('BTG Cartão'!$C:$C,'BTG Cartão'!$E:$E,$A16,'BTG Cartão'!$F:$F,B$4,'BTG Cartão'!$D:$D,"saída")),0) | C16: =IFERROR(-(SUMIFS('Itaú CC'!$C:$C,'Itaú CC'!$E:$E,$A16,'Itaú CC'!$F:$F,C$4,'Itaú CC'!$D:$D,"saída")+SUMIFS('Itaú Cartão'!$C:$C,'Itaú Cartão'!$E:$E,$A16,'Itaú Cartão'!$F:$F,C$4,'Itaú Cartão'!$D:$D,"saída")+SUMIFS('BTG Cartão'!$C:$C,'BTG Cartão'!$E:$E,$A16,'BTG Cartão'!$F:$F,C$4,'BTG Cartão'!$D:$D,"saída")),0) | D16: =IFERROR(-(SUMIFS('Itaú CC'!$C:$C,'Itaú CC'!$E:$E,$A16,'Itaú CC'!$F:$F,D$4,'Itaú CC'!$D:$D,"saída")+SUMIFS('Itaú Cartão'!$C:$C,'Itaú Cartão'!$E:$E,$A16,'Itaú Cartão'!$F:$F,D$4,'Itaú Cartão'!$D:$D,"saída")+SUMIFS('BTG Cartão'!$C:$C,'BTG Cartão'!$E:$E,$A16,'BTG Cartão'!$F:$F,D$4,'BTG Cartão'!$D:$D,"saída")),0) | E16: =IFERROR(-(SUMIFS('Itaú CC'!$C:$C,'Itaú CC'!$E:$E,$A16,'Itaú CC'!$F:$F,E$4,'Itaú CC'!$D:$D,"saída")+SUMIFS('Itaú Cartão'!$C:$C,'Itaú Cartão'!$E:$E,$A16,'Itaú Cartão'!$F:$F,E$4,'Itaú Cartão'!$D:$D,"saída")+SUMIFS('BTG Cartão'!$C:$C,'BTG Cartão'!$E:$E,$A16,'BTG Cartão'!$F:$F,E$4,'BTG Cartão'!$D:$D,"saída")),0) | F16: =IFERROR(-(SUMIFS('Itaú CC'!$C:$C,'Itaú CC'!$E:$E,$A16,'Itaú CC'!$F:$F,F$4,'Itaú CC'!$D:$D,"saída")+SUMIFS('Itaú Cartão'!$C:$C,'Itaú Cartão'!$E:$E,$A16,'Itaú Cartão'!$F:$F,F$4,'Itaú Cartão'!$D:$D,"saída")+SUMIFS('BTG Cartão'!$C:$C,'BTG Cartão'!$E:$E,$A16,'BTG Cartão'!$F:$F,F$4,'BTG Cartão'!$D:$D,"saída")),0) | G16: =IFERROR(-(SUMIFS('Itaú CC'!$C:$C,'Itaú CC'!$E:$E,$A16,'Itaú CC'!$F:$F,G$4,'Itaú CC'!$D:$D,"saída")+SUMIFS('Itaú Cartão'!$C:$C,'Itaú Cartão'!$E:$E,$A16,'Itaú Cartão'!$F:$F,G$4,'Itaú Cartão'!$D:$D,"saída")+SUMIFS('BTG Cartão'!$C:$C,'BTG Cartão'!$E:$E,$A16,'BTG Cartão'!$F:$F,G$4,'BTG Cartão'!$D:$D,"saída")),0) | H16: =IFERROR(-(SUMIFS('Itaú CC'!$C:$C,'Itaú CC'!$E:$E,$A16,'Itaú CC'!$F:$F,H$4,'Itaú CC'!$D:$D,"saída")+SUMIFS('Itaú Cartão'!$C:$C,'Itaú Cartão'!$E:$E,$A16,'Itaú Cartão'!$F:$F,H$4,'Itaú Cartão'!$D:$D,"saída")+SUMIFS('BTG Cartão'!$C:$C,'BTG Cartão'!$E:$E,$A16,'BTG Cartão'!$F:$F,H$4,'BTG Cartão'!$D:$D,"saída")),0) | I16: =IFERROR(-(SUMIFS('Itaú CC'!$C:$C,'Itaú CC'!$E:$E,$A16,'Itaú CC'!$F:$F,I$4,'Itaú CC'!$D:$D,"saída")+SUMIFS('Itaú Cartão'!$C:$C,'Itaú Cartão'!$E:$E,$A16,'Itaú Cartão'!$F:$F,I$4,'Itaú Cartão'!$D:$D,"saída")+SUMIFS('BTG Cartão'!$C:$C,'BTG Cartão'!$E:$E,$A16,'BTG Cartão'!$F:$F,I$4,'BTG Cartão'!$D:$D,"saída")),0) | J16: =IFERROR(-(SUMIFS('Itaú CC'!$C:$C,'Itaú CC'!$E:$E,$A16,'Itaú CC'!$F:$F,J$4,'Itaú CC'!$D:$D,"saída")+SUMIFS('Itaú Cartão'!$C:$C,'Itaú Cartão'!$E:$E,$A16,'Itaú Cartão'!$F:$F,J$4,'Itaú Cartão'!$D:$D,"saída")+SUMIFS('BTG Cartão'!$C:$C,'BTG Cartão'!$E:$E,$A16,'BTG Cartão'!$F:$F,J$4,'BTG Cartão'!$D:$D,"saída")),0) | K16: =SUM(B16:J16)
... A36: ⚠ LR-PR | B36: =IFERROR(-(SUMIFS('Itaú CC'!$C:$C,'Itaú CC'!$E:$E,$A36,'Itaú CC'!$F:$F,B$4,'Itaú CC'!$D:$D,"saída")+SUMIFS('Itaú Cartão'!$C:$C,'Itaú Cartão'!$E:$E,$A36,'Itaú Cartão'!$F:$F,B$4,'Itaú Cartão'!$D:$D,"saída")+SUMIFS('BTG Cartão'!$C:$C,'BTG Cartão'!$E:$E,$A36,'BTG Cartão'!$F:$F,B$4,'BTG Cartão'!$D:$D,"saída")),0) | C36: =IFERROR(-(SUMIFS('Itaú CC'!$C:$C,'Itaú CC'!$E:$E,$A36,'Itaú CC'!$F:$F,C$4,'Itaú CC'!$D:$D,"saída")+SUMIFS('Itaú Cartão'!$C:$C,'Itaú Cartão'!$E:$E,$A36,'Itaú Cartão'!$F:$F,C$4,'Itaú Cartão'!$D:$D,"saída")+SUMIFS('BTG Cartão'!$C:$C,'BTG Cartão'!$E:$E,$A36,'BTG Cartão'!$F:$F,C$4,'BTG Cartão'!$D:$D,"saída")),0) | D36: =IFERROR(-(SUMIFS('Itaú CC'!$C:$C,'Itaú CC'!$E:$E,$A36,'Itaú CC'!$F:$F,D$4,'Itaú CC'!$D:$D,"saída")+SUMIFS('Itaú Cartão'!$C:$C,'Itaú Cartão'!$E:$E,$A36,'Itaú Cartão'!$F:$F,D$4,'Itaú Cartão'!$D:$D,"saída")+SUMIFS('BTG Cartão'!$C:$C,'BTG Cartão'!$E:$E,$A36,'BTG Cartão'!$F:$F,D$4,'BTG Cartão'!$D:$D,"saída")),0) | E36: =IFERROR(-(SUMIFS('Itaú CC'!$C:$C,'Itaú CC'!$E:$E,$A36,'Itaú CC'!$F:$F,E$4,'Itaú CC'!$D:$D,"saída")+SUMIFS('Itaú Cartão'!$C:$C,'Itaú Cartão'!$E:$E,$A36,'Itaú Cartão'!$F:$F,E$4,'Itaú Cartão'!$D:$D,"saída")+SUMIFS('BTG Cartão'!$C:$C,'BTG Cartão'!$E:$E,$A36,'BTG Cartão'!$F:$F,E$4,'BTG Cartão'!$D:$D,"saída")),0) | F36: =IFERROR(-(SUMIFS('Itaú CC'!$C:$C,'Itaú CC'!$E:$E,$A36,'Itaú CC'!$F:$F,F$4,'Itaú CC'!$D:$D,"saída")+SUMIFS('Itaú Cartão'!$C:$C,'Itaú Cartão'!$E:$E,$A36,'Itaú Cartão'!$F:$F,F$4,'Itaú Cartão'!$D:$D,"saída")+SUMIFS('BTG Cartão'!$C:$C,'BTG Cartão'!$E:$E,$A36,'BTG Cartão'!$F:$F,F$4,'BTG Cartão'!$D:$D,"saída")),0) | G36: =IFERROR(-(SUMIFS('Itaú CC'!$C:$C,'Itaú CC'!$E:$E,$A36,'Itaú CC'!$F:$F,G$4,'Itaú CC'!$D:$D,"saída")+SUMIFS('Itaú Cartão'!$C:$C,'Itaú Cartão'!$E:$E,$A36,'Itaú Cartão'!$F:$F,G$4,'Itaú Cartão'!$D:$D,"saída")+SUMIFS('BTG Cartão'!$C:$C,'BTG Cartão'!$E:$E,$A36,'BTG Cartão'!$F:$F,G$4,'BTG Cartão'!$D:$D,"saída")),0) | H36: =IFERROR(-(SUMIFS('Itaú CC'!$C:$C,'Itaú CC'!$E:$E,$A36,'Itaú CC'!$F:$F,H$4,'Itaú CC'!$D:$D,"saída")+SUMIFS('Itaú Cartão'!$C:$C,'Itaú Cartão'!$E:$E,$A36,'Itaú Cartão'!$F:$F,H$4,'Itaú Cartão'!$D:$D,"saída")+SUMIFS('BTG Cartão'!$C:$C,'BTG Cartão'!$E:$E,$A36,'BTG Cartão'!$F:$F,H$4,'BTG Cartão'!$D:$D,"saída")),0) | I36: =IFERROR(-(SUMIFS('Itaú CC'!$C:$C,'Itaú CC'!$E:$E,$A36,'Itaú CC'!$F:$F,I$4,'Itaú CC'!$D:$D,"saída")+SUMIFS('Itaú Cartão'!$C:$C,'Itaú Cartão'!$E:$E,$A36,'Itaú Cartão'!$F:$F,I$4,'Itaú Cartão'!$D:$D,"saída")+SUMIFS('BTG Cartão'!$C:$C,'BTG Cartão'!$E:$E,$A36,'BTG Cartão'!$F:$F,I$4,'BTG Cartão'!$D:$D,"saída")),0) | J36: =IFERROR(-(SUMIFS('Itaú CC'!$C:$C,'Itaú CC'!$E:$E,$A36,'Itaú CC'!$F:$F,J$4,'Itaú CC'!$D:$D,"saída")+SUMIFS('Itaú Cartão'!$C:$C,'Itaú Cartão'!$E:$E,$A36,'Itaú Cartão'!$F:$F,J$4,'Itaú Cartão'!$D:$D,"saída")+SUMIFS('BTG Cartão'!$C:$C,'BTG Cartão'!$E:$E,$A36,'BTG Cartão'!$F:$F,J$4,'BTG Cartão'!$D:$D,"saída")),0) | K36: =SUM(B36:J36)
A37: TOTAL | B37: =SUM(B5:B36) | C37: =SUM(C5:C36) | D37: =SUM(D5:D36) | E37: =SUM(E5:E36) | F37: =SUM(F5:F36) | G37: =SUM(G5:G36) | H37: =SUM(H5:H36) | I37: =SUM(I5:I36) | ... K37: =SUM(K5:K36)
A39: ▲ ENTRADAS POR CATEGORIA
A40: Categoria | B40: 2025-07 | C40: 2025-08 | D40: 2025-09 | E40: 2025-10 | F40: 2025-11 | G40: 2025-12 | H40: 2026-01 | I40: 2026-02 | J40: 2026-03 | K40: Total
A41: Dividendo Semestral Nord | B41: =IFERROR(SUMIFS('Itaú CC'!$C:$C,'Itaú CC'!$E:$E,$A41,'Itaú CC'!$F:$F,B$40,'Itaú CC'!$D:$D,"entrada")+SUMIFS('Itaú Cartão'!$C:$C,'Itaú Cartão'!$E:$E,$A41,'Itaú Cartão'!$F:$F,B$40,'Itaú Cartão'!$D:$D,"entrada")+SUMIFS('BTG Cartão'!$C:$C,'BTG Cartão'!$E:$E,$A41,'BTG Cartão'!$F:$F,B$40,'BTG Cartão'!$D:$D,"entrada"),0) | C41: =IFERROR(SUMIFS('Itaú CC'!$C:$C,'Itaú CC'!$E:$E,$A41,'Itaú CC'!$F:$F,C$40,'Itaú CC'!$D:$D,"entrada")+SUMIFS('Itaú Cartão'!$C:$C,'Itaú Cartão'!$E:$E,$A41,'Itaú Cartão'!$F:$F,C$40,'Itaú Cartão'!$D:$D,"entrada")+SUMIFS('BTG Cartão'!$C:$C,'BTG Cartão'!$E:$E,$A41,'BTG Cartão'!$F:$F,C$40,'BTG Cartão'!$D:$D,"entrada"),0) | D41: =IFERROR(SUMIFS('Itaú CC'!$C:$C,'Itaú CC'!$E:$E,$A41,'Itaú CC'!$F:$F,D$40,'Itaú CC'!$D:$D,"entrada")+SUMIFS('Itaú Cartão'!$C:$C,'Itaú Cartão'!$E:$E,$A41,'Itaú Cartão'!$F:$F,D$40,'Itaú Cartão'!$D:$D,"entrada")+SUMIFS('BTG Cartão'!$C:$C,'BTG Cartão'!$E:$E,$A41,'BTG Cartão'!$F:$F,D$40,'BTG Cartão'!$D:$D,"entrada"),0) | E41: =IFERROR(SUMIFS('Itaú CC'!$C:$C,'Itaú CC'!$E:$E,$A41,'Itaú CC'!$F:$F,E$40,'Itaú CC'!$D:$D,"entrada")+SUMIFS('Itaú Cartão'!$C:$C,'Itaú Cartão'!$E:$E,$A41,'Itaú Cartão'!$F:$F,E$40,'Itaú Cartão'!$D:$D,"entrada")+SUMIFS('BTG Cartão'!$C:$C,'BTG Cartão'!$E:$E,$A41,'BTG Cartão'!$F:$F,E$40,'BTG Cartão'!$D:$D,"entrada"),0) | F41: =IFERROR(SUMIFS('Itaú CC'!$C:$C,'Itaú CC'!$E:$E,$A41,'Itaú CC'!$F:$F,F$40,'Itaú CC'!$D:$D,"entrada")+SUMIFS('Itaú Cartão'!$C:$C,'Itaú Cartão'!$E:$E,$A41,'Itaú Cartão'!$F:$F,F$40,'Itaú Cartão'!$D:$D,"entrada")+SUMIFS('BTG Cartão'!$C:$C,'BTG Cartão'!$E:$E,$A41,'BTG Cartão'!$F:$F,F$40,'BTG Cartão'!$D:$D,"entrada"),0) | G41: =IFERROR(SUMIFS('Itaú CC'!$C:$C,'Itaú CC'!$E:$E,$A41,'Itaú CC'!$F:$F,G$40,'Itaú CC'!$D:$D,"entrada")+SUMIFS('Itaú Cartão'!$C:$C,'Itaú Cartão'!$E:$E,$A41,'Itaú Cartão'!$F:$F,G$40,'Itaú Cartão'!$D:$D,"entrada")+SUMIFS('BTG Cartão'!$C:$C,'BTG Cartão'!$E:$E,$A41,'BTG Cartão'!$F:$F,G$40,'BTG Cartão'!$D:$D,"entrada"),0) | H41: =IFERROR(SUMIFS('Itaú CC'!$C:$C,'Itaú CC'!$E:$E,$A41,'Itaú CC'!$F:$F,H$40,'Itaú CC'!$D:$D,"entrada")+SUMIFS('Itaú Cartão'!$C:$C,'Itaú Cartão'!$E:$E,$A41,'Itaú Cartão'!$F:$F,H$40,'Itaú Cartão'!$D:$D,"entrada")+SUMIFS('BTG Cartão'!$C:$C,'BTG Cartão'!$E:$E,$A41,'BTG Cartão'!$F:$F,H$40,'BTG Cartão'!$D:$D,"entrada"),0) | I41: =IFERROR(SUMIFS('Itaú CC'!$C:$C,'Itaú CC'!$E:$E,$A41,'Itaú CC'!$F:$F,I$40,'Itaú CC'!$D:$D,"entrada")+SUMIFS('Itaú Cartão'!$C:$C,'Itaú Cartão'!$E:$E,$A41,'Itaú Cartão'!$F:$F,I$40,'Itaú Cartão'!$D:$D,"entrada")+SUMIFS('BTG Cartão'!$C:$C,'BTG Cartão'!$E:$E,$A41,'BTG Cartão'!$F:$F,I$40,'BTG Cartão'!$D:$D,"entrada"),0) | J41: =IFERROR(SUMIFS('Itaú CC'!$C:$C,'Itaú CC'!$E:$E,$A41,'Itaú CC'!$F:$F,J$40,'Itaú CC'!$D:$D,"entrada")+SUMIFS('Itaú Cartão'!$C:$C,'Itaú Cartão'!$E:$E,$A41,'Itaú Cartão'!$F:$F,J$40,'Itaú Cartão'!$D:$D,"entrada")+SUMIFS('BTG Cartão'!$C:$C,'BTG Cartão'!$E:$E,$A41,'BTG Cartão'!$F:$F,J$40,'BTG Cartão'!$D:$D,"entrada"),0) | K41: =SUM(B41:J41)
A42: Dividendos Nord | B42: =IFERROR(SUMIFS('Itaú CC'!$C:$C,'Itaú CC'!$E:$E,$A42,'Itaú CC'!$F:$F,B$40,'Itaú CC'!$D:$D,"entrada")+SUMIFS('Itaú Cartão'!$C:$C,'Itaú Cartão'!$E:$E,$A42,'Itaú Cartão'!$F:$F,B$40,'Itaú Cartão'!$D:$D,"entrada")+SUMIFS('BTG Cartão'!$C:$C,'BTG Cartão'!$E:$E,$A42,'BTG Cartão'!$F:$F,B$40,'BTG Cartão'!$D:$D,"entrada"),0) | C42: =IFERROR(SUMIFS('Itaú CC'!$C:$C,'Itaú CC'!$E:$E,$A42,'Itaú CC'!$F:$F,C$40,'Itaú CC'!$D:$D,"entrada")+SUMIFS('Itaú Cartão'!$C:$C,'Itaú Cartão'!$E:$E,$A42,'Itaú Cartão'!$F:$F,C$40,'Itaú Cartão'!$D:$D,"entrada")+SUMIFS('BTG Cartão'!$C:$C,'BTG Cartão'!$E:$E,$A42,'BTG Cartão'!$F:$F,C$40,'BTG Cartão'!$D:$D,"entrada"),0) | D42: =IFERROR(SUMIFS('Itaú CC'!$C:$C,'Itaú CC'!$E:$E,$A42,'Itaú CC'!$F:$F,D$40,'Itaú CC'!$D:$D,"entrada")+SUMIFS('Itaú Cartão'!$C:$C,'Itaú Cartão'!$E:$E,$A42,'Itaú Cartão'!$F:$F,D$40,'Itaú Cartão'!$D:$D,"entrada")+SUMIFS('BTG Cartão'!$C:$C,'BTG Cartão'!$E:$E,$A42,'BTG Cartão'!$F:$F,D$40,'BTG Cartão'!$D:$D,"entrada"),0) | E42: =IFERROR(SUMIFS('Itaú CC'!$C:$C,'Itaú CC'!$E:$E,$A42,'Itaú CC'!$F:$F,E$40,'Itaú CC'!$D:$D,"entrada")+SUMIFS('Itaú Cartão'!$C:$C,'Itaú Cartão'!$E:$E,$A42,'Itaú Cartão'!$F:$F,E$40,'Itaú Cartão'!$D:$D,"entrada")+SUMIFS('BTG Cartão'!$C:$C,'BTG Cartão'!$E:$E,$A42,'BTG Cartão'!$F:$F,E$40,'BTG Cartão'!$D:$D,"entrada"),0) | F42: =IFERROR(SUMIFS('Itaú CC'!$C:$C,'Itaú CC'!$E:$E,$A42,'Itaú CC'!$F:$F,F$40,'Itaú CC'!$D:$D,"entrada")+SUMIFS('Itaú Cartão'!$C:$C,'Itaú Cartão'!$E:$E,$A42,'Itaú Cartão'!$F:$F,F$40,'Itaú Cartão'!$D:$D,"entrada")+SUMIFS('BTG Cartão'!$C:$C,'BTG Cartão'!$E:$E,$A42,'BTG Cartão'!$F:$F,F$40,'BTG Cartão'!$D:$D,"entrada"),0) | G42: =IFERROR(SUMIFS('Itaú CC'!$C:$C,'Itaú CC'!$E:$E,$A42,'Itaú CC'!$F:$F,G$40,'Itaú CC'!$D:$D,"entrada")+SUMIFS('Itaú Cartão'!$C:$C,'Itaú Cartão'!$E:$E,$A42,'Itaú Cartão'!$F:$F,G$40,'Itaú Cartão'!$D:$D,"entrada")+SUMIFS('BTG Cartão'!$C:$C,'BTG Cartão'!$E:$E,$A42,'BTG Cartão'!$F:$F,G$40,'BTG Cartão'!$D:$D,"entrada"),0) | H42: =IFERROR(SUMIFS('Itaú CC'!$C:$C,'Itaú CC'!$E:$E,$A42,'Itaú CC'!$F:$F,H$40,'Itaú CC'!$D:$D,"entrada")+SUMIFS('Itaú Cartão'!$C:$C,'Itaú Cartão'!$E:$E,$A42,'Itaú Cartão'!$F:$F,H$40,'Itaú Cartão'!$D:$D,"entrada")+SUMIFS('BTG Cartão'!$C:$C,'BTG Cartão'!$E:$E,$A42,'BTG Cartão'!$F:$F,H$40,'BTG Cartão'!$D:$D,"entrada"),0) | I42: =IFERROR(SUMIFS('Itaú CC'!$C:$C,'Itaú CC'!$E:$E,$A42,'Itaú CC'!$F:$F,I$40,'Itaú CC'!$D:$D,"entrada")+SUMIFS('Itaú Cartão'!$C:$C,'Itaú Cartão'!$E:$E,$A42,'Itaú Cartão'!$F:$F,I$40,'Itaú Cartão'!$D:$D,"entrada")+SUMIFS('BTG Cartão'!$C:$C,'BTG Cartão'!$E:$E,$A42,'BTG Cartão'!$F:$F,I$40,'BTG Cartão'!$D:$D,"entrada"),0) | J42: =IFERROR(SUMIFS('Itaú CC'!$C:$C,'Itaú CC'!$E:$E,$A42,'Itaú CC'!$F:$F,J$40,'Itaú CC'!$D:$D,"entrada")+SUMIFS('Itaú Cartão'!$C:$C,'Itaú Cartão'!$E:$E,$A42,'Itaú Cartão'!$F:$F,J$40,'Itaú Cartão'!$D:$D,"entrada")+SUMIFS('BTG Cartão'!$C:$C,'BTG Cartão'!$E:$E,$A42,'BTG Cartão'!$F:$F,J$40,'BTG Cartão'!$D:$D,"entrada"),0) | K42: =SUM(B42:J42)
A43: Outros | B43: =IFERROR(SUMIFS('Itaú CC'!$C:$C,'Itaú CC'!$E:$E,$A43,'Itaú CC'!$F:$F,B$40,'Itaú CC'!$D:$D,"entrada")+SUMIFS('Itaú Cartão'!$C:$C,'Itaú Cartão'!$E:$E,$A43,'Itaú Cartão'!$F:$F,B$40,'Itaú Cartão'!$D:$D,"entrada")+SUMIFS('BTG Cartão'!$C:$C,'BTG Cartão'!$E:$E,$A43,'BTG Cartão'!$F:$F,B$40,'BTG Cartão'!$D:$D,"entrada"),0) | C43: =IFERROR(SUMIFS('Itaú CC'!$C:$C,'Itaú CC'!$E:$E,$A43,'Itaú CC'!$F:$F,C$40,'Itaú CC'!$D:$D,"entrada")+SUMIFS('Itaú Cartão'!$C:$C,'Itaú Cartão'!$E:$E,$A43,'Itaú Cartão'!$F:$F,C$40,'Itaú Cartão'!$D:$D,"entrada")+SUMIFS('BTG Cartão'!$C:$C,'BTG Cartão'!$E:$E,$A43,'BTG Cartão'!$F:$F,C$40,'BTG Cartão'!$D:$D,"entrada"),0) | D43: =IFERROR(SUMIFS('Itaú CC'!$C:$C,'Itaú CC'!$E:$E,$A43,'Itaú CC'!$F:$F,D$40,'Itaú CC'!$D:$D,"entrada")+SUMIFS('Itaú Cartão'!$C:$C,'Itaú Cartão'!$E:$E,$A43,'Itaú Cartão'!$F:$F,D$40,'Itaú Cartão'!$D:$D,"entrada")+SUMIFS('BTG Cartão'!$C:$C,'BTG Cartão'!$E:$E,$A43,'BTG Cartão'!$F:$F,D$40,'BTG Cartão'!$D:$D,"entrada"),0) | E43: =IFERROR(SUMIFS('Itaú CC'!$C:$C,'Itaú CC'!$E:$E,$A43,'Itaú CC'!$F:$F,E$40,'Itaú CC'!$D:$D,"entrada")+SUMIFS('Itaú Cartão'!$C:$C,'Itaú Cartão'!$E:$E,$A43,'Itaú Cartão'!$F:$F,E$40,'Itaú Cartão'!$D:$D,"entrada")+SUMIFS('BTG Cartão'!$C:$C,'BTG Cartão'!$E:$E,$A43,'BTG Cartão'!$F:$F,E$40,'BTG Cartão'!$D:$D,"entrada"),0) | F43: =IFERROR(SUMIFS('Itaú CC'!$C:$C,'Itaú CC'!$E:$E,$A43,'Itaú CC'!$F:$F,F$40,'Itaú CC'!$D:$D,"entrada")+SUMIFS('Itaú Cartão'!$C:$C,'Itaú Cartão'!$E:$E,$A43,'Itaú Cartão'!$F:$F,F$40,'Itaú Cartão'!$D:$D,"entrada")+SUMIFS('BTG Cartão'!$C:$C,'BTG Cartão'!$E:$E,$A43,'BTG Cartão'!$F:$F,F$40,'BTG Cartão'!$D:$D,"entrada"),0) | G43: =IFERROR(SUMIFS('Itaú CC'!$C:$C,'Itaú CC'!$E:$E,$A43,'Itaú CC'!$F:$F,G$40,'Itaú CC'!$D:$D,"entrada")+SUMIFS('Itaú Cartão'!$C:$C,'Itaú Cartão'!$E:$E,$A43,'Itaú Cartão'!$F:$F,G$40,'Itaú Cartão'!$D:$D,"entrada")+SUMIFS('BTG Cartão'!$C:$C,'BTG Cartão'!$E:$E,$A43,'BTG Cartão'!$F:$F,G$40,'BTG Cartão'!$D:$D,"entrada"),0) | H43: =IFERROR(SUMIFS('Itaú CC'!$C:$C,'Itaú CC'!$E:$E,$A43,'Itaú CC'!$F:$F,H$40,'Itaú CC'!$D:$D,"entrada")+SUMIFS('Itaú Cartão'!$C:$C,'Itaú Cartão'!$E:$E,$A43,'Itaú Cartão'!$F:$F,H$40,'Itaú Cartão'!$D:$D,"entrada")+SUMIFS('BTG Cartão'!$C:$C,'BTG Cartão'!$E:$E,$A43,'BTG Cartão'!$F:$F,H$40,'BTG Cartão'!$D:$D,"entrada"),0) | I43: =IFERROR(SUMIFS('Itaú CC'!$C:$C,'Itaú CC'!$E:$E,$A43,'Itaú CC'!$F:$F,I$40,'Itaú CC'!$D:$D,"entrada")+SUMIFS('Itaú Cartão'!$C:$C,'Itaú Cartão'!$E:$E,$A43,'Itaú Cartão'!$F:$F,I$40,'Itaú Cartão'!$D:$D,"entrada")+SUMIFS('BTG Cartão'!$C:$C,'BTG Cartão'!$E:$E,$A43,'BTG Cartão'!$F:$F,I$40,'BTG Cartão'!$D:$D,"entrada"),0) | J43: =IFERROR(SUMIFS('Itaú CC'!$C:$C,'Itaú CC'!$E:$E,$A43,'Itaú CC'!$F:$F,J$40,'Itaú CC'!$D:$D,"entrada")+SUMIFS('Itaú Cartão'!$C:$C,'Itaú Cartão'!$E:$E,$A43,'Itaú Cartão'!$F:$F,J$40,'Itaú Cartão'!$D:$D,"entrada")+SUMIFS('BTG Cartão'!$C:$C,'BTG Cartão'!$E:$E,$A43,'BTG Cartão'!$F:$F,J$40,'BTG Cartão'!$D:$D,"entrada"),0) | K43: =SUM(B43:J43)
A44: Reembolso | B44: =IFERROR(SUMIFS('Itaú CC'!$C:$C,'Itaú CC'!$E:$E,$A44,'Itaú CC'!$F:$F,B$40,'Itaú CC'!$D:$D,"entrada")+SUMIFS('Itaú Cartão'!$C:$C,'Itaú Cartão'!$E:$E,$A44,'Itaú Cartão'!$F:$F,B$40,'Itaú Cartão'!$D:$D,"entrada")+SUMIFS('BTG Cartão'!$C:$C,'BTG Cartão'!$E:$E,$A44,'BTG Cartão'!$F:$F,B$40,'BTG Cartão'!$D:$D,"entrada"),0) | C44: =IFERROR(SUMIFS('Itaú CC'!$C:$C,'Itaú CC'!$E:$E,$A44,'Itaú CC'!$F:$F,C$40,'Itaú CC'!$D:$D,"entrada")+SUMIFS('Itaú Cartão'!$C:$C,'Itaú Cartão'!$E:$E,$A44,'Itaú Cartão'!$F:$F,C$40,'Itaú Cartão'!$D:$D,"entrada")+SUMIFS('BTG Cartão'!$C:$C,'BTG Cartão'!$E:$E,$A44,'BTG Cartão'!$F:$F,C$40,'BTG Cartão'!$D:$D,"entrada"),0) | D44: =IFERROR(SUMIFS('Itaú CC'!$C:$C,'Itaú CC'!$E:$E,$A44,'Itaú CC'!$F:$F,D$40,'Itaú CC'!$D:$D,"entrada")+SUMIFS('Itaú Cartão'!$C:$C,'Itaú Cartão'!$E:$E,$A44,'Itaú Cartão'!$F:$F,D$40,'Itaú Cartão'!$D:$D,"entrada")+SUMIFS('BTG Cartão'!$C:$C,'BTG Cartão'!$E:$E,$A44,'BTG Cartão'!$F:$F,D$40,'BTG Cartão'!$D:$D,"entrada"),0) | E44: =IFERROR(SUMIFS('Itaú CC'!$C:$C,'Itaú CC'!$E:$E,$A44,'Itaú CC'!$F:$F,E$40,'Itaú CC'!$D:$D,"entrada")+SUMIFS('Itaú Cartão'!$C:$C,'Itaú Cartão'!$E:$E,$A44,'Itaú Cartão'!$F:$F,E$40,'Itaú Cartão'!$D:$D,"entrada")+SUMIFS('BTG Cartão'!$C:$C,'BTG Cartão'!$E:$E,$A44,'BTG Cartão'!$F:$F,E$40,'BTG Cartão'!$D:$D,"entrada"),0) | F44: =IFERROR(SUMIFS('Itaú CC'!$C:$C,'Itaú CC'!$E:$E,$A44,'Itaú CC'!$F:$F,F$40,'Itaú CC'!$D:$D,"entrada")+SUMIFS('Itaú Cartão'!$C:$C,'Itaú Cartão'!$E:$E,$A44,'Itaú Cartão'!$F:$F,F$40,'Itaú Cartão'!$D:$D,"entrada")+SUMIFS('BTG Cartão'!$C:$C,'BTG Cartão'!$E:$E,$A44,'BTG Cartão'!$F:$F,F$40,'BTG Cartão'!$D:$D,"entrada"),0) | G44: =IFERROR(SUMIFS('Itaú CC'!$C:$C,'Itaú CC'!$E:$E,$A44,'Itaú CC'!$F:$F,G$40,'Itaú CC'!$D:$D,"entrada")+SUMIFS('Itaú Cartão'!$C:$C,'Itaú Cartão'!$E:$E,$A44,'Itaú Cartão'!$F:$F,G$40,'Itaú Cartão'!$D:$D,"entrada")+SUMIFS('BTG Cartão'!$C:$C,'BTG Cartão'!$E:$E,$A44,'BTG Cartão'!$F:$F,G$40,'BTG Cartão'!$D:$D,"entrada"),0) | H44: =IFERROR(SUMIFS('Itaú CC'!$C:$C,'Itaú CC'!$E:$E,$A44,'Itaú CC'!$F:$F,H$40,'Itaú CC'!$D:$D,"entrada")+SUMIFS('Itaú Cartão'!$C:$C,'Itaú Cartão'!$E:$E,$A44,'Itaú Cartão'!$F:$F,H$40,'Itaú Cartão'!$D:$D,"entrada")+SUMIFS('BTG Cartão'!$C:$C,'BTG Cartão'!$E:$E,$A44,'BTG Cartão'!$F:$F,H$40,'BTG Cartão'!$D:$D,"entrada"),0) | I44: =IFERROR(SUMIFS('Itaú CC'!$C:$C,'Itaú CC'!$E:$E,$A44,'Itaú CC'!$F:$F,I$40,'Itaú CC'!$D:$D,"entrada")+SUMIFS('Itaú Cartão'!$C:$C,'Itaú Cartão'!$E:$E,$A44,'Itaú Cartão'!$F:$F,I$40,'Itaú Cartão'!$D:$D,"entrada")+SUMIFS('BTG Cartão'!$C:$C,'BTG Cartão'!$E:$E,$A44,'BTG Cartão'!$F:$F,I$40,'BTG Cartão'!$D:$D,"entrada"),0) | J44: =IFERROR(SUMIFS('Itaú CC'!$C:$C,'Itaú CC'!$E:$E,$A44,'Itaú CC'!$F:$F,J$40,'Itaú CC'!$D:$D,"entrada")+SUMIFS('Itaú Cartão'!$C:$C,'Itaú Cartão'!$E:$E,$A44,'Itaú Cartão'!$F:$F,J$40,'Itaú Cartão'!$D:$D,"entrada")+SUMIFS('BTG Cartão'!$C:$C,'BTG Cartão'!$E:$E,$A44,'BTG Cartão'!$F:$F,J$40,'BTG Cartão'!$D:$D,"entrada"),0) | K44: =SUM(B44:J44)
A45: Rendimentos | B45: =IFERROR(SUMIFS('Itaú CC'!$C:$C,'Itaú CC'!$E:$E,$A45,'Itaú CC'!$F:$F,B$40,'Itaú CC'!$D:$D,"entrada")+SUMIFS('Itaú Cartão'!$C:$C,'Itaú Cartão'!$E:$E,$A45,'Itaú Cartão'!$F:$F,B$40,'Itaú Cartão'!$D:$D,"entrada")+SUMIFS('BTG Cartão'!$C:$C,'BTG Cartão'!$E:$E,$A45,'BTG Cartão'!$F:$F,B$40,'BTG Cartão'!$D:$D,"entrada"),0) | C45: =IFERROR(SUMIFS('Itaú CC'!$C:$C,'Itaú CC'!$E:$E,$A45,'Itaú CC'!$F:$F,C$40,'Itaú CC'!$D:$D,"entrada")+SUMIFS('Itaú Cartão'!$C:$C,'Itaú Cartão'!$E:$E,$A45,'Itaú Cartão'!$F:$F,C$40,'Itaú Cartão'!$D:$D,"entrada")+SUMIFS('BTG Cartão'!$C:$C,'BTG Cartão'!$E:$E,$A45,'BTG Cartão'!$F:$F,C$40,'BTG Cartão'!$D:$D,"entrada"),0) | D45: =IFERROR(SUMIFS('Itaú CC'!$C:$C,'Itaú CC'!$E:$E,$A45,'Itaú CC'!$F:$F,D$40,'Itaú CC'!$D:$D,"entrada")+SUMIFS('Itaú Cartão'!$C:$C,'Itaú Cartão'!$E:$E,$A45,'Itaú Cartão'!$F:$F,D$40,'Itaú Cartão'!$D:$D,"entrada")+SUMIFS('BTG Cartão'!$C:$C,'BTG Cartão'!$E:$E,$A45,'BTG Cartão'!$F:$F,D$40,'BTG Cartão'!$D:$D,"entrada"),0) | E45: =IFERROR(SUMIFS('Itaú CC'!$C:$C,'Itaú CC'!$E:$E,$A45,'Itaú CC'!$F:$F,E$40,'Itaú CC'!$D:$D,"entrada")+SUMIFS('Itaú Cartão'!$C:$C,'Itaú Cartão'!$E:$E,$A45,'Itaú Cartão'!$F:$F,E$40,'Itaú Cartão'!$D:$D,"entrada")+SUMIFS('BTG Cartão'!$C:$C,'BTG Cartão'!$E:$E,$A45,'BTG Cartão'!$F:$F,E$40,'BTG Cartão'!$D:$D,"entrada"),0) | F45: =IFERROR(SUMIFS('Itaú CC'!$C:$C,'Itaú CC'!$E:$E,$A45,'Itaú CC'!$F:$F,F$40,'Itaú CC'!$D:$D,"entrada")+SUMIFS('Itaú Cartão'!$C:$C,'Itaú Cartão'!$E:$E,$A45,'Itaú Cartão'!$F:$F,F$40,'Itaú Cartão'!$D:$D,"entrada")+SUMIFS('BTG Cartão'!$C:$C,'BTG Cartão'!$E:$E,$A45,'BTG Cartão'!$F:$F,F$40,'BTG Cartão'!$D:$D,"entrada"),0) | G45: =IFERROR(SUMIFS('Itaú CC'!$C:$C,'Itaú CC'!$E:$E,$A45,'Itaú CC'!$F:$F,G$40,'Itaú CC'!$D:$D,"entrada")+SUMIFS('Itaú Cartão'!$C:$C,'Itaú Cartão'!$E:$E,$A45,'Itaú Cartão'!$F:$F,G$40,'Itaú Cartão'!$D:$D,"entrada")+SUMIFS('BTG Cartão'!$C:$C,'BTG Cartão'!$E:$E,$A45,'BTG Cartão'!$F:$F,G$40,'BTG Cartão'!$D:$D,"entrada"),0) | H45: =IFERROR(SUMIFS('Itaú CC'!$C:$C,'Itaú CC'!$E:$E,$A45,'Itaú CC'!$F:$F,H$40,'Itaú CC'!$D:$D,"entrada")+SUMIFS('Itaú Cartão'!$C:$C,'Itaú Cartão'!$E:$E,$A45,'Itaú Cartão'!$F:$F,H$40,'Itaú Cartão'!$D:$D,"entrada")+SUMIFS('BTG Cartão'!$C:$C,'BTG Cartão'!$E:$E,$A45,'BTG Cartão'!$F:$F,H$40,'BTG Cartão'!$D:$D,"entrada"),0) | I45: =IFERROR(SUMIFS('Itaú CC'!$C:$C,'Itaú CC'!$E:$E,$A45,'Itaú CC'!$F:$F,I$40,'Itaú CC'!$D:$D,"entrada")+SUMIFS('Itaú Cartão'!$C:$C,'Itaú Cartão'!$E:$E,$A45,'Itaú Cartão'!$F:$F,I$40,'Itaú Cartão'!$D:$D,"entrada")+SUMIFS('BTG Cartão'!$C:$C,'BTG Cartão'!$E:$E,$A45,'BTG Cartão'!$F:$F,I$40,'BTG Cartão'!$D:$D,"entrada"),0) | J45: =IFERROR(SUMIFS('Itaú CC'!$C:$C,'Itaú CC'!$E:$E,$A45,'Itaú CC'!$F:$F,J$40,'Itaú CC'!$D:$D,"entrada")+SUMIFS('Itaú Cartão'!$C:$C,'Itaú Cartão'!$E:$E,$A45,'Itaú Cartão'!$F:$F,J$40,'Itaú Cartão'!$D:$D,"entrada")+SUMIFS('BTG Cartão'!$C:$C,'BTG Cartão'!$E:$E,$A45,'BTG Cartão'!$F:$F,J$40,'BTG Cartão'!$D:$D,"entrada"),0) | K45: =SUM(B45:J45)
A46: Resgate CDB | B46: =IFERROR(SUMIFS('Itaú CC'!$C:$C,'Itaú CC'!$E:$E,$A46,'Itaú CC'!$F:$F,B$40,'Itaú CC'!$D:$D,"entrada")+SUMIFS('Itaú Cartão'!$C:$C,'Itaú Cartão'!$E:$E,$A46,'Itaú Cartão'!$F:$F,B$40,'Itaú Cartão'!$D:$D,"entrada")+SUMIFS('BTG Cartão'!$C:$C,'BTG Cartão'!$E:$E,$A46,'BTG Cartão'!$F:$F,B$40,'BTG Cartão'!$D:$D,"entrada"),0) | C46: =IFERROR(SUMIFS('Itaú CC'!$C:$C,'Itaú CC'!$E:$E,$A46,'Itaú CC'!$F:$F,C$40,'Itaú CC'!$D:$D,"entrada")+SUMIFS('Itaú Cartão'!$C:$C,'Itaú Cartão'!$E:$E,$A46,'Itaú Cartão'!$F:$F,C$40,'Itaú Cartão'!$D:$D,"entrada")+SUMIFS('BTG Cartão'!$C:$C,'BTG Cartão'!$E:$E,$A46,'BTG Cartão'!$F:$F,C$40,'BTG Cartão'!$D:$D,"entrada"),0) | D46: =IFERROR(SUMIFS('Itaú CC'!$C:$C,'Itaú CC'!$E:$E,$A46,'Itaú CC'!$F:$F,D$40,'Itaú CC'!$D:$D,"entrada")+SUMIFS('Itaú Cartão'!$C:$C,'Itaú Cartão'!$E:$E,$A46,'Itaú Cartão'!$F:$F,D$40,'Itaú Cartão'!$D:$D,"entrada")+SUMIFS('BTG Cartão'!$C:$C,'BTG Cartão'!$E:$E,$A46,'BTG Cartão'!$F:$F,D$40,'BTG Cartão'!$D:$D,"entrada"),0) | E46: =IFERROR(SUMIFS('Itaú CC'!$C:$C,'Itaú CC'!$E:$E,$A46,'Itaú CC'!$F:$F,E$40,'Itaú CC'!$D:$D,"entrada")+SUMIFS('Itaú Cartão'!$C:$C,'Itaú Cartão'!$E:$E,$A46,'Itaú Cartão'!$F:$F,E$40,'Itaú Cartão'!$D:$D,"entrada")+SUMIFS('BTG Cartão'!$C:$C,'BTG Cartão'!$E:$E,$A46,'BTG Cartão'!$F:$F,E$40,'BTG Cartão'!$D:$D,"entrada"),0) | F46: =IFERROR(SUMIFS('Itaú CC'!$C:$C,'Itaú CC'!$E:$E,$A46,'Itaú CC'!$F:$F,F$40,'Itaú CC'!$D:$D,"entrada")+SUMIFS('Itaú Cartão'!$C:$C,'Itaú Cartão'!$E:$E,$A46,'Itaú Cartão'!$F:$F,F$40,'Itaú Cartão'!$D:$D,"entrada")+SUMIFS('BTG Cartão'!$C:$C,'BTG Cartão'!$E:$E,$A46,'BTG Cartão'!$F:$F,F$40,'BTG Cartão'!$D:$D,"entrada"),0) | G46: =IFERROR(SUMIFS('Itaú CC'!$C:$C,'Itaú CC'!$E:$E,$A46,'Itaú CC'!$F:$F,G$40,'Itaú CC'!$D:$D,"entrada")+SUMIFS('Itaú Cartão'!$C:$C,'Itaú Cartão'!$E:$E,$A46,'Itaú Cartão'!$F:$F,G$40,'Itaú Cartão'!$D:$D,"entrada")+SUMIFS('BTG Cartão'!$C:$C,'BTG Cartão'!$E:$E,$A46,'BTG Cartão'!$F:$F,G$40,'BTG Cartão'!$D:$D,"entrada"),0) | H46: =IFERROR(SUMIFS('Itaú CC'!$C:$C,'Itaú CC'!$E:$E,$A46,'Itaú CC'!$F:$F,H$40,'Itaú CC'!$D:$D,"entrada")+SUMIFS('Itaú Cartão'!$C:$C,'Itaú Cartão'!$E:$E,$A46,'Itaú Cartão'!$F:$F,H$40,'Itaú Cartão'!$D:$D,"entrada")+SUMIFS('BTG Cartão'!$C:$C,'BTG Cartão'!$E:$E,$A46,'BTG Cartão'!$F:$F,H$40,'BTG Cartão'!$D:$D,"entrada"),0) | I46: =IFERROR(SUMIFS('Itaú CC'!$C:$C,'Itaú CC'!$E:$E,$A46,'Itaú CC'!$F:$F,I$40,'Itaú CC'!$D:$D,"entrada")+SUMIFS('Itaú Cartão'!$C:$C,'Itaú Cartão'!$E:$E,$A46,'Itaú Cartão'!$F:$F,I$40,'Itaú Cartão'!$D:$D,"entrada")+SUMIFS('BTG Cartão'!$C:$C,'BTG Cartão'!$E:$E,$A46,'BTG Cartão'!$F:$F,I$40,'BTG Cartão'!$D:$D,"entrada"),0) | J46: =IFERROR(SUMIFS('Itaú CC'!$C:$C,'Itaú CC'!$E:$E,$A46,'Itaú CC'!$F:$F,J$40,'Itaú CC'!$D:$D,"entrada")+SUMIFS('Itaú Cartão'!$C:$C,'Itaú Cartão'!$E:$E,$A46,'Itaú Cartão'!$F:$F,J$40,'Itaú Cartão'!$D:$D,"entrada")+SUMIFS('BTG Cartão'!$C:$C,'BTG Cartão'!$E:$E,$A46,'BTG Cartão'!$F:$F,J$40,'BTG Cartão'!$D:$D,"entrada"),0) | K46: =SUM(B46:J46)
A47: Salário | B47: =IFERROR(SUMIFS('Itaú CC'!$C:$C,'Itaú CC'!$E:$E,$A47,'Itaú CC'!$F:$F,B$40,'Itaú CC'!$D:$D,"entrada")+SUMIFS('Itaú Cartão'!$C:$C,'Itaú Cartão'!$E:$E,$A47,'Itaú Cartão'!$F:$F,B$40,'Itaú Cartão'!$D:$D,"entrada")+SUMIFS('BTG Cartão'!$C:$C,'BTG Cartão'!$E:$E,$A47,'BTG Cartão'!$F:$F,B$40,'BTG Cartão'!$D:$D,"entrada"),0) | C47: =IFERROR(SUMIFS('Itaú CC'!$C:$C,'Itaú CC'!$E:$E,$A47,'Itaú CC'!$F:$F,C$40,'Itaú CC'!$D:$D,"entrada")+SUMIFS('Itaú Cartão'!$C:$C,'Itaú Cartão'!$E:$E,$A47,'Itaú Cartão'!$F:$F,C$40,'Itaú Cartão'!$D:$D,"entrada")+SUMIFS('BTG Cartão'!$C:$C,'BTG Cartão'!$E:$E,$A47,'BTG Cartão'!$F:$F,C$40,'BTG Cartão'!$D:$D,"entrada"),0) | D47: =IFERROR(SUMIFS('Itaú CC'!$C:$C,'Itaú CC'!$E:$E,$A47,'Itaú CC'!$F:$F,D$40,'Itaú CC'!$D:$D,"entrada")+SUMIFS('Itaú Cartão'!$C:$C,'Itaú Cartão'!$E:$E,$A47,'Itaú Cartão'!$F:$F,D$40,'Itaú Cartão'!$D:$D,"entrada")+SUMIFS('BTG Cartão'!$C:$C,'BTG Cartão'!$E:$E,$A47,'BTG Cartão'!$F:$F,D$40,'BTG Cartão'!$D:$D,"entrada"),0) | E47: =IFERROR(SUMIFS('Itaú CC'!$C:$C,'Itaú CC'!$E:$E,$A47,'Itaú CC'!$F:$F,E$40,'Itaú CC'!$D:$D,"entrada")+SUMIFS('Itaú Cartão'!$C:$C,'Itaú Cartão'!$E:$E,$A47,'Itaú Cartão'!$F:$F,E$40,'Itaú Cartão'!$D:$D,"entrada")+SUMIFS('BTG Cartão'!$C:$C,'BTG Cartão'!$E:$E,$A47,'BTG Cartão'!$F:$F,E$40,'BTG Cartão'!$D:$D,"entrada"),0) | F47: =IFERROR(SUMIFS('Itaú CC'!$C:$C,'Itaú CC'!$E:$E,$A47,'Itaú CC'!$F:$F,F$40,'Itaú CC'!$D:$D,"entrada")+SUMIFS('Itaú Cartão'!$C:$C,'Itaú Cartão'!$E:$E,$A47,'Itaú Cartão'!$F:$F,F$40,'Itaú Cartão'!$D:$D,"entrada")+SUMIFS('BTG Cartão'!$C:$C,'BTG Cartão'!$E:$E,$A47,'BTG Cartão'!$F:$F,F$40,'BTG Cartão'!$D:$D,"entrada"),0) | G47: =IFERROR(SUMIFS('Itaú CC'!$C:$C,'Itaú CC'!$E:$E,$A47,'Itaú CC'!$F:$F,G$40,'Itaú CC'!$D:$D,"entrada")+SUMIFS('Itaú Cartão'!$C:$C,'Itaú Cartão'!$E:$E,$A47,'Itaú Cartão'!$F:$F,G$40,'Itaú Cartão'!$D:$D,"entrada")+SUMIFS('BTG Cartão'!$C:$C,'BTG Cartão'!$E:$E,$A47,'BTG Cartão'!$F:$F,G$40,'BTG Cartão'!$D:$D,"entrada"),0) | H47: =IFERROR(SUMIFS('Itaú CC'!$C:$C,'Itaú CC'!$E:$E,$A47,'Itaú CC'!$F:$F,H$40,'Itaú CC'!$D:$D,"entrada")+SUMIFS('Itaú Cartão'!$C:$C,'Itaú Cartão'!$E:$E,$A47,'Itaú Cartão'!$F:$F,H$40,'Itaú Cartão'!$D:$D,"entrada")+SUMIFS('BTG Cartão'!$C:$C,'BTG Cartão'!$E:$E,$A47,'BTG Cartão'!$F:$F,H$40,'BTG Cartão'!$D:$D,"entrada"),0) | I47: =IFERROR(SUMIFS('Itaú CC'!$C:$C,'Itaú CC'!$E:$E,$A47,'Itaú CC'!$F:$F,I$40,'Itaú CC'!$D:$D,"entrada")+SUMIFS('Itaú Cartão'!$C:$C,'Itaú Cartão'!$E:$E,$A47,'Itaú Cartão'!$F:$F,I$40,'Itaú Cartão'!$D:$D,"entrada")+SUMIFS('BTG Cartão'!$C:$C,'BTG Cartão'!$E:$E,$A47,'BTG Cartão'!$F:$F,I$40,'BTG Cartão'!$D:$D,"entrada"),0) | J47: =IFERROR(SUMIFS('Itaú CC'!$C:$C,'Itaú CC'!$E:$E,$A47,'Itaú CC'!$F:$F,J$40,'Itaú CC'!$D:$D,"entrada")+SUMIFS('Itaú Cartão'!$C:$C,'Itaú Cartão'!$E:$E,$A47,'Itaú Cartão'!$F:$F,J$40,'Itaú Cartão'!$D:$D,"entrada")+SUMIFS('BTG Cartão'!$C:$C,'BTG Cartão'!$E:$E,$A47,'BTG Cartão'!$F:$F,J$40,'BTG Cartão'!$D:$D,"entrada"),0) | K47: =SUM(B47:J47)
